Workbook

Sheet PAINEL_PESOS
A1: DINÂMICA DE PONDERAÇÃO POR ESPECIALISTAS — ISH 2025
A3: Edite somente as células amarelas. Os pesos internos de cada dimensão e os pesos das dimensões devem somar 100%.
A5: NÍVEL 2 — PESOS DAS DIMENSÕES
A6: Dimensão | B6: Peso escolhido | C6: Peso Beta | D6: Diferença | E6: Regra | F6: Status
A7: Humana | B7: 0.25 | C7: 0.25 | D7: =B7-C7 | E7: 0% a 100%
A8: Econômica | B8: 0.25 | C8: 0.25 | D8: =B8-C8 | E8: 0% a 100%
A9: Ecossistêmica | B9: 0.25 | C9: 0.25 | D9: =B9-C9 | E9: 0% a 100%
A10: Resiliência | B10: 0.25 | C10: 0.25 | D10: =B10-C10 | E10: 0% a 100%
A12: Soma dos pesos | B12: =SUM(B7:B10) | C12: Validação | D12: =IF(ABS(B12-1)<0.000001,"OK - 100%","AJUSTAR - deve somar 100%")
A14: NÍVEL 1 — PESOS DAS VARIÁVEIS DENTRO DE CADA DIMENSÃO
A15: Dimensão | B15: Variável | C15: Peso escolhido | D15: Peso padrão | E15: Diferença | F15: Status da dimensão
A16: Humana | B16: Abastecimento | C16: 0.25 | D16: 0.25 | E16: =C16-D16
A17: Humana | B17: Potabilidade | C17: 0.25 | D17: 0.25 | E17: =C17-D17
A18: Humana | B18: Perdas (invertida) | C18: 0.25 | D18: 0.25 | E18: =C18-D18
A19: Humana | B19: Segurança hídrica humana | C19: 0.25 | D19: 0.25 | E19: =C19-D19
A20: Humana | B20: SOMA | C20: =SUM(C16:C19) | D20: 1 | F20: =IF(ABS(C20-1)<0.000001,"OK - 100%","AJUSTAR")
A21: Econômica | B21: PIB | C21: 0.33333333 | D21: 0.33333333 | E21: =C21-D21
A22: Econômica | B22: Segurança industrial | C22: 0.33333333 | D22: 0.33333333 | E22: =C22-D22
A23: Econômica | B23: Segurança agropecuária | C23: 0.33333333 | D23: 0.33333333 | E23: =C23-D23
A24: Econômica | B24: SOMA | C24: =SUM(C21:C23) | D24: 1 | F24: =IF(ABS(C24-1)<0.000001,"OK - 100%","AJUSTAR")
A25: Ecossistêmica | B25: Cobertura florestal | C25: 0.5 | D25: 0.5 | E25: =C25-D25
A26: Ecossistêmica | B26: Segurança associada à DBO | C26: 0.5 | D26: 0.5 | E26: =C26-D26
A27: Ecossistêmica | B27: SOMA | C27: =SUM(C25:C26) | D27: 1 | F27: =IF(ABS(C27-1)<0.000001,"OK - 100%","AJUSTAR")
A28: Resiliência | B28: SPI-12 | C28: 0.5 | D28: 0.5 | E28: =C28-D28
A29: Resiliência | B29: CV pluviométrico | C29: 0.5 | D29: 0.5 | E29: =C29-D29
A30: Resiliência | B30: SOMA | C30: =SUM(C28:C29) | D30: 1 | F30: =IF(ABS(C30-1)<0.000001,"OK - 100%","AJUSTAR")
A32: REGRA DO CÁLCULO
A33: Cada dimensão é recalculada pela soma ponderada de suas variáveis. Depois, as quatro dimensões recebem os pesos do Nível 2. O fator Q95 permanece transversal e fixo, sem receber peso. O resultado só é exibido quando todos os grupos somam 100%.

Sheet RESULTADOS_MUNICIPIOS
A1: cod_ibge | B1: Município | C1: UF | D1: Região | E1: Humana ponderada | F1: Econômica ponderada | G1: Ecossistêmica ponderada | H1: Resiliência ponderada | I1: Fator Q95 | J1: ISH Beta 25/25/25/25 | K1: ISH com pesos escolhidos | L1: Diferença vs Beta | M1: Diferença absoluta | N1: Abastecimento | O1: Potabilidade | P1: Perdas_inv | Q1: Seg_humana_hidrica | R1: PIB | S1: Seg_industrial | T1: Seg_agro | U1: Cobertura_florestal | V1: DBO_inv | W1: SPI12 | X1: CV_pluv_inv
A2: 1100015 | B2: Alta Floresta D'Oeste | C2: RO | D2: REGIÃO NORTE | E2: =SUMPRODUCT(N2:Q2,PAINEL_PESOS!$C$16:$C$19) | F2: =SUMPRODUCT(R2:T2,PAINEL_PESOS!$C$21:$C$23) | G2: =SUMPRODUCT(U2:V2,PAINEL_PESOS!$C$25:$C$26) | H2: =SUMPRODUCT(W2:X2,PAINEL_PESOS!$C$28:$C$29) | I2: 0.9968011 | J2: 0.67442049 | K2: =IF(NOT(AND(PAINEL_PESOS!$D$12="OK - 100%",PAINEL_PESOS!$F$20="OK - 100%",PAINEL_PESOS!$F$24="OK - 100%",PAINEL_PESOS!$F$27="OK - 100%",PAINEL_PESOS!$F$30="OK - 100%")),"", (E2*PAINEL_PESOS!$B$7+F2*PAINEL_PESOS!$B$8+G2*PAINEL_PESOS!$B$9+H2*PAINEL_PESOS!$B$10)*I2) | L2: =IF(K2="","",K2-J2) | M2: =IF(L2="","",ABS(L2)) | N2: 0.4 | O2: 1 | P2: 0.3500528 | Q2: 0.9995823 | R2: 0.34956347 | S2: 0.99994735 | T2: 0.98398654 | U2: 0.5447275 | V2: 0.29944518 | W2: 0.71289627 | X2: 0.92512714
A3: 1100023 | B3: Ariquemes | C3: RO | D3: REGIÃO NORTE | E3: =SUMPRODUCT(N3:Q3,PAINEL_PESOS!$C$16:$C$19) | F3: =SUMPRODUCT(R3:T3,PAINEL_PESOS!$C$21:$C$23) | G3: =SUMPRODUCT(U3:V3,PAINEL_PESOS!$C$25:$C$26) | H3: =SUMPRODUCT(W3:X3,PAINEL_PESOS!$C$28:$C$29) | I3: 0.99842651 | J3: 0.6910795 | K3: =IF(NOT(AND(PAINEL_PESOS!$D$12="OK - 100%",PAINEL_PESOS!$F$20="OK - 100%",PAINEL_PESOS!$F$24="OK - 100%",PAINEL_PESOS!$F$27="OK - 100%",PAINEL_PESOS!$F$30="OK - 100%")),"", (E3*PAINEL_PESOS!$B$7+F3*PAINEL_PESOS!$B$8+G3*PAINEL_PESOS!$B$9+H3*PAINEL_PESOS!$B$10)*I3) | L3: =IF(K3="","",K3-J3) | M3: =IF(L3="","",ABS(L3)) | N3: 0.4 | O3: 0.9974 | P3: 0.65987328 | Q3: 0.99497859 | R3: 0.48408171 | S3: 0.99918995 | T3: 0.99621681 | U3: 0.42541133 | V3: 0.29886843 | W3: 0.67482989 | X3: 0.95912104
A4: 1100031 | B4: Cabixi | C4: RO | D4: REGIÃO NORTE | E4: =SUMPRODUCT(N4:Q4,PAINEL_PESOS!$C$16:$C$19) | F4: =SUMPRODUCT(R4:T4,PAINEL_PESOS!$C$21:$C$23) | G4: =SUMPRODUCT(U4:V4,PAINEL_PESOS!$C$25:$C$26) | H4: =SUMPRODUCT(W4:X4,PAINEL_PESOS!$C$28:$C$29) | I4: 0.99876286 | J4: 0.71477542 | K4: =IF(NOT(AND(PAINEL_PESOS!$D$12="OK - 100%",PAINEL_PESOS!$F$20="OK - 100%",PAINEL_PESOS!$F$24="OK - 100%",PAINEL_PESOS!$F$27="OK - 100%",PAINEL_PESOS!$F$30="OK - 100%")),"", (E4*PAINEL_PESOS!$B$7+F4*PAINEL_PESOS!$B$8+G4*PAINEL_PESOS!$B$9+H4*PAINEL_PESOS!$B$10)*I4) | L4: =IF(K4="","",K4-J4) | M4: =IF(L4="","",ABS(L4)) | N4: 1 | O4: 1 | P4: 0.52228089 | Q4: 0.99969967 | R4: 0.23252086 | S4: 0.99994431 | T4: 0.99392816 | U4: 0.3766196 | V4: 0.33270908 | W4: 0.85243237 | X4: 0.91827279
A5: 1100049 | B5: Cacoal | C5: RO | D5: REGIÃO NORTE | E5: =SUMPRODUCT(N5:Q5,PAINEL_PESOS!$C$16:$C$19) | F5: =SUMPRODUCT(R5:T5,PAINEL_PESOS!$C$21:$C$23) | G5: =SUMPRODUCT(U5:V5,PAINEL_PESOS!$C$25:$C$26) | H5: =SUMPRODUCT(W5:X5,PAINEL_PESOS!$C$28:$C$29) | I5: 0.99501716 | J5: 0.72366518 | K5: =IF(NOT(AND(PAINEL_PESOS!$D$12="OK - 100%",PAINEL_PESOS!$F$20="OK - 100%",PAINEL_PESOS!$F$24="OK - 100%",PAINEL_PESOS!$F$27="OK - 100%",PAINEL_PESOS!$F$30="OK - 100%")),"", (E5*PAINEL_PESOS!$B$7+F5*PAINEL_PESOS!$B$8+G5*PAINEL_PESOS!$B$9+H5*PAINEL_PESOS!$B$10)*I5) | L5: =IF(K5="","",K5-J5) | M5: =IF(L5="","",ABS(L5)) | N5: 1 | O5: 0.7122 | P5: 0.53790919 | Q5: 0.99624203 | R5: 0.47185219 | S5: 0.99932338 | T5: 0.97753007 | U5: 0.67159389 | V5: 0.29790092 | W5: 0.60290183 | X5: 0.99027047
A6: 1100056 | B6: Cerejeiras | C6: RO | D6: REGIÃO NORTE | E6: =SUMPRODUCT(N6:Q6,PAINEL_PESOS!$C$16:$C$19) | F6: =SUMPRODUCT(R6:T6,PAINEL_PESOS!$C$21:$C$23) | G6: =SUMPRODUCT(U6:V6,PAINEL_PESOS!$C$25:$C$26) | H6: =SUMPRODUCT(W6:X6,PAINEL_PESOS!$C$28:$C$29) | I6: 0.9995116 | J6: 0.66851928 | K6: =IF(NOT(AND(PAINEL_PESOS!$D$12="OK - 100%",PAINEL_PESOS!$F$20="OK - 100%",PAINEL_PESOS!$F$24="OK - 100%",PAINEL_PESOS!$F$27="OK - 100%",PAINEL_PESOS!$F$30="OK - 100%")),"", (E6*PAINEL_PESOS!$B$7+F6*PAINEL_PESOS!$B$8+G6*PAINEL_PESOS!$B$9+H6*PAINEL_PESOS!$B$10)*I6) | L6: =IF(K6="","",K6-J6) | M6: =IF(L6="","",ABS(L6)) | N6: 0.2 | O6: 1 | P6: 0.49007392 | Q6: 0.99911857 | R6: 0.34590783 | S6: 0.99985152 | T6: 0.99822641 | U6: 0.43010798 | V6: 0.31513299 | W6: 0.78683343 | X6: 0.91143978
A7: 1100064 | B7: Colorado do Oeste | C7: RO | D7: REGIÃO NORTE | E7: =SUMPRODUCT(N7:Q7,PAINEL_PESOS!$C$16:$C$19) | F7: =SUMPRODUCT(R7:T7,PAINEL_PESOS!$C$21:$C$23) | G7: =SUMPRODUCT(U7:V7,PAINEL_PESOS!$C$25:$C$26) | H7: =SUMPRODUCT(W7:X7,PAINEL_PESOS!$C$28:$C$29) | I7: 0.99865532 | J7: 0.70537515 | K7: =IF(NOT(AND(PAINEL_PESOS!$D$12="OK - 100%",PAINEL_PESOS!$F$20="OK - 100%",PAINEL_PESOS!$F$24="OK - 100%",PAINEL_PESOS!$F$27="OK - 100%",PAINEL_PESOS!$F$30="OK - 100%")),"", (E7*PAINEL_PESOS!$B$7+F7*PAINEL_PESOS!$B$8+G7*PAINEL_PESOS!$B$9+H7*PAINEL_PESOS!$B$10)*I7) | L7: =IF(K7="","",K7-J7) | M7: =IF(L7="","",ABS(L7)) | N7: 1 | O7: 1 | P7: 0.32428722 | Q7: 0.99856903 | R7: 0.29430717 | S7: 0.99961798 | T7: 0.99435691 | U7: 0.37777324 | V7: 0.31791725 | W7: 0.84890894 | X7: 0.9190505
A8: 1100072 | B8: Corumbiara | C8: RO | D8: REGIÃO NORTE | E8: =SUMPRODUCT(N8:Q8,PAINEL_PESOS!$C$16:$C$19) | F8: =SUMPRODUCT(R8:T8,PAINEL_PESOS!$C$21:$C$23) | G8: =SUMPRODUCT(U8:V8,PAINEL_PESOS!$C$25:$C$26) | H8: =SUMPRODUCT(W8:X8,PAINEL_PESOS!$C$28:$C$29) | I8: 0.99918456 | J8: 0.71988683 | K8: =IF(NOT(AND(PAINEL_PESOS!$D$12="OK - 100%",PAINEL_PESOS!$F$20="OK - 100%",PAINEL_PESOS!$F$24="OK - 100%",PAINEL_PESOS!$F$27="OK - 100%",PAINEL_PESOS!$F$30="OK - 100%")),"", (E8*PAINEL_PESOS!$B$7+F8*PAINEL_PESOS!$B$8+G8*PAINEL_PESOS!$B$9+H8*PAINEL_PESOS!$B$10)*I8) | L8: =IF(K8="","",K8-J8) | M8: =IF(L8="","",ABS(L8)) | N8: 1 | O8: 1 | P8: 0.64920803 | Q8: 0.99977625 | R8: 0.28200506 | S8: 0.99997512 | T8: 0.99601149 | U8: 0.49016383 | V8: 0.31423203 | W8: 0.71192876 | X8: 0.90431676
A9: 1100080 | B9: Costa Marques | C9: RO | D9: REGIÃO NORTE | E9: =SUMPRODUCT(N9:Q9,PAINEL_PESOS!$C$16:$C$19) | F9: =SUMPRODUCT(R9:T9,PAINEL_PESOS!$C$21:$C$23) | G9: =SUMPRODUCT(U9:V9,PAINEL_PESOS!$C$25:$C$26) | H9: =SUMPRODUCT(W9:X9,PAINEL_PESOS!$C$28:$C$29) | I9: 0.99899257 | J9: 0.64632413 | K9: =IF(NOT(AND(PAINEL_PESOS!$D$12="OK - 100%",PAINEL_PESOS!$F$20="OK - 100%",PAINEL_PESOS!$F$24="OK - 100%",PAINEL_PESOS!$F$27="OK - 100%",PAINEL_PESOS!$F$30="OK - 100%")),"", (E9*PAINEL_PESOS!$B$7+F9*PAINEL_PESOS!$B$8+G9*PAINEL_PESOS!$B$9+H9*PAINEL_PESOS!$B$10)*I9) | L9: =IF(K9="","",K9-J9) | M9: =IF(L9="","",ABS(L9)) | N9: 0.2 | O9: 1 | P9: 0.22925026 | Q9: 0.99858746 | R9: 0.26249042 | S9: 0.99999634 | T9: 0.99590423 | U9: 0.51566942 | V9: 0.30141227 | W9: 0.80057775 | X9: 0.83863505
A10: 1100098 | B10: Espigão D'Oeste | C10: RO | D10: REGIÃO NORTE | E10: =SUMPRODUCT(N10:Q10,PAINEL_PESOS!$C$16:$C$19) | F10: =SUMPRODUCT(R10:T10,PAINEL_PESOS!$C$21:$C$23) | G10: =SUMPRODUCT(U10:V10,PAINEL_PESOS!$C$25:$C$26) | H10: =SUMPRODUCT(W10:X10,PAINEL_PESOS!$C$28:$C$29) | I10: 0.99916769 | J10: 0.71042478 | K10: =IF(NOT(AND(PAINEL_PESOS!$D$12="OK - 100%",PAINEL_PESOS!$F$20="OK - 100%",PAINEL_PESOS!$F$24="OK - 100%",PAINEL_PESOS!$F$27="OK - 100%",PAINEL_PESOS!$F$30="OK - 100%")),"", (E10*PAINEL_PESOS!$B$7+F10*PAINEL_PESOS!$B$8+G10*PAINEL_PESOS!$B$9+H10*PAINEL_PESOS!$B$10)*I10) | L10: =IF(K10="","",K10-J10) | M10: =IF(L10="","",ABS(L10)) | N10: 0.2 | O10: 1 | P10: 0.69482577 | Q10: 0.9994271 | R10: 0.34753426 | S10: 0.999574 | T10: 0.99639405 | U10: 0.77118846 | V10: 0.31276806 | W10: 0.60714554 | X10: 0.9875692
A11: 1100106 | B11: Guajará-Mirim | C11: RO | D11: REGIÃO NORTE | E11: =SUMPRODUCT(N11:Q11,PAINEL_PESOS!$C$16:$C$19) | F11: =SUMPRODUCT(R11:T11,PAINEL_PESOS!$C$21:$C$23) | G11: =SUMPRODUCT(U11:V11,PAINEL_PESOS!$C$25:$C$26) | H11: =SUMPRODUCT(W11:X11,PAINEL_PESOS!$C$28:$C$29) | I11: 0.99990875 | J11: 0.71189551 | K11: =IF(NOT(AND(PAINEL_PESOS!$D$12="OK - 100%",PAINEL_PESOS!$F$20="OK - 100%",PAINEL_PESOS!$F$24="OK - 100%",PAINEL_PESOS!$F$27="OK - 100%",PAINEL_PESOS!$F$30="OK - 100%")),"", (E11*PAINEL_PESOS!$B$7+F11*PAINEL_PESOS!$B$8+G11*PAINEL_PESOS!$B$9+H11*PAINEL_PESOS!$B$10)*I11) | L11: =IF(K11="","",K11-J11) | M11: =IF(L11="","",ABS(L11)) | N11: 0.2 | O11: 1 | P11: 0.4279831 | Q11: 0.99964007 | R11: 0.35802667 | S11: 0.99997894 | T11: 0.99981194 | U11: 0.90492128 | V11: 0.30156078 | W11: 0.79459475 | X11: 0.80891701
A12: 1100114 | B12: Jaru | C12: RO | D12: REGIÃO NORTE | E12: =SUMPRODUCT(N12:Q12,PAINEL_PESOS!$C$16:$C$19) | F12: =SUMPRODUCT(R12:T12,PAINEL_PESOS!$C$21:$C$23) | G12: =SUMPRODUCT(U12:V12,PAINEL_PESOS!$C$25:$C$26) | H12: =SUMPRODUCT(W12:X12,PAINEL_PESOS!$C$28:$C$29) | I12: 0.99766957 | J12: 0.65501633 | K12: =IF(NOT(AND(PAINEL_PESOS!$D$12="OK - 100%",PAINEL_PESOS!$F$20="OK - 100%",PAINEL_PESOS!$F$24="OK - 100%",PAINEL_PESOS!$F$27="OK - 100%",PAINEL_PESOS!$F$30="OK - 100%")),"", (E12*PAINEL_PESOS!$B$7+F12*PAINEL_PESOS!$B$8+G12*PAINEL_PESOS!$B$9+H12*PAINEL_PESOS!$B$10)*I12) | L12: =IF(K12="","",K12-J12) | M12: =IF(L12="","",ABS(L12)) | N12: 0.2 | O12: 1 | P12: 0.44213305 | Q12: 0.99622378 | R12: 0.4319291 | S12: 0.99695708 | T12: 0.99218675 | U12: 0.42974988 | V12: 0.2990014 | W12: 0.59438197 | X12: 0.99601061
A13: 1100122 | B13: Ji-Paraná | C13: RO | D13: REGIÃO NORTE | E13: =SUMPRODUCT(N13:Q13,PAINEL_PESOS!$C$16:$C$19) | F13: =SUMPRODUCT(R13:T13,PAINEL_PESOS!$C$21:$C$23) | G13: =SUMPRODUCT(U13:V13,PAINEL_PESOS!$C$25:$C$26) | H13: =SUMPRODUCT(W13:X13,PAINEL_PESOS!$C$28:$C$29) | I13: 0.99894396 | J13: 0.66460453 | K13: =IF(NOT(AND(PAINEL_PESOS!$D$12="OK - 100%",PAINEL_PESOS!$F$20="OK - 100%",PAINEL_PESOS!$F$24="OK - 100%",PAINEL_PESOS!$F$27="OK - 100%",PAINEL_PESOS!$F$30="OK - 100%")),"", (E13*PAINEL_PESOS!$B$7+F13*PAINEL_PESOS!$B$8+G13*PAINEL_PESOS!$B$9+H13*PAINEL_PESOS!$B$10)*I13) | L13: =IF(K13="","",K13-J13) | M13: =IF(L13="","",ABS(L13)) | N13: 0.2 | O13: 1 | P13: 0.46853221 | Q13: 0.99660696 | R13: 0.51076239 | S13: 0.99856002 | T13: 0.99775921 | U13: 0.43143748 | V13: 0.29760925 | W13: 0.59266879 | X13: 0.99678413
... A580: 2107456 | B580: Olinda Nova do Maranhão | C580: MA | D580: REGIÃO NORDESTE | E580: =SUMPRODUCT(N580:Q580,PAINEL_PESOS!$C$16:$C$19) | F580: =SUMPRODUCT(R580:T580,PAINEL_PESOS!$C$21:$C$23) | G580: =SUMPRODUCT(U580:V580,PAINEL_PESOS!$C$25:$C$26) | H580: =SUMPRODUCT(W580:X580,PAINEL_PESOS!$C$28:$C$29) | I580: 0.96967369 | J580: 0.64523955 | K580: =IF(NOT(AND(PAINEL_PESOS!$D$12="OK - 100%",PAINEL_PESOS!$F$20="OK - 100%",PAINEL_PESOS!$F$24="OK - 100%",PAINEL_PESOS!$F$27="OK - 100%",PAINEL_PESOS!$F$30="OK - 100%")),"", (E580*PAINEL_PESOS!$B$7+F580*PAINEL_PESOS!$B$8+G580*PAINEL_PESOS!$B$9+H580*PAINEL_PESOS!$B$10)*I580) | L580: =IF(K580="","",K580-J580) | M580: =IF(L580="","",ABS(L580)) | N580: 0.2 | O580: 1 | P580: 1 | Q580: 0.81647003 | R580: 0.15571351 | S580: 0.99994539 | T580: 0.97714668 | U580: 0.39459972 | V580: 0.5768387 | W580: 0.69105024 | X580: 0.73076
A581: 2107506 | B581: Paço do Lumiar | C581: MA | D581: REGIÃO NORDESTE | E581: =SUMPRODUCT(N581:Q581,PAINEL_PESOS!$C$16:$C$19) | F581: =SUMPRODUCT(R581:T581,PAINEL_PESOS!$C$21:$C$23) | G581: =SUMPRODUCT(U581:V581,PAINEL_PESOS!$C$25:$C$26) | H581: =SUMPRODUCT(W581:X581,PAINEL_PESOS!$C$28:$C$29) | I581: 0.86208722 | K581: =IF(NOT(AND(PAINEL_PESOS!$D$12="OK - 100%",PAINEL_PESOS!$F$20="OK - 100%",PAINEL_PESOS!$F$24="OK - 100%",PAINEL_PESOS!$F$27="OK - 100%",PAINEL_PESOS!$F$30="OK - 100%")),"", (E581*PAINEL_PESOS!$B$7+F581*PAINEL_PESOS!$B$8+G581*PAINEL_PESOS!$B$9+H581*PAINEL_PESOS!$B$10)*I581) | L581: =IF(K581="","",K581-J581) | M581: =IF(L581="","",ABS(L581)) | N581: 0.6 | O581: 0.98 | P581: 0.36219641 | Q581: 0.27138528 | R581: 0.39196249 | S581: 0.9556738 | T581: 0.64745055 | V581: 0.56752713
A582: 2107605 | B582: Palmeirândia | C582: MA | D582: REGIÃO NORDESTE | E582: =SUMPRODUCT(N582:Q582,PAINEL_PESOS!$C$16:$C$19) | F582: =SUMPRODUCT(R582:T582,PAINEL_PESOS!$C$21:$C$23) | G582: =SUMPRODUCT(U582:V582,PAINEL_PESOS!$C$25:$C$26) | H582: =SUMPRODUCT(W582:X582,PAINEL_PESOS!$C$28:$C$29) | I582: 0.97405958 | J582: 0.647462 | K582: =IF(NOT(AND(PAINEL_PESOS!$D$12="OK - 100%",PAINEL_PESOS!$F$20="OK - 100%",PAINEL_PESOS!$F$24="OK - 100%",PAINEL_PESOS!$F$27="OK - 100%",PAINEL_PESOS!$F$30="OK - 100%")),"", (E582*PAINEL_PESOS!$B$7+F582*PAINEL_PESOS!$B$8+G582*PAINEL_PESOS!$B$9+H582*PAINEL_PESOS!$B$10)*I582) | L582: =IF(K582="","",K582-J582) | M582: =IF(L582="","",ABS(L582)) | N582: 1 | O582: 0.2414 | P582: 0.40232313 | Q582: 0.92155606 | R582: 0.18847405 | S582: 1 | T582: 0.91804871 | U582: 0.60002919 | V582: 0.57573251 | W582: 0.72990954 | X582: 0.72497843
A583: 2107704 | B583: Paraibano | C583: MA | D583: REGIÃO NORDESTE | E583: =SUMPRODUCT(N583:Q583,PAINEL_PESOS!$C$16:$C$19) | F583: =SUMPRODUCT(R583:T583,PAINEL_PESOS!$C$21:$C$23) | G583: =SUMPRODUCT(U583:V583,PAINEL_PESOS!$C$25:$C$26) | H583: =SUMPRODUCT(W583:X583,PAINEL_PESOS!$C$28:$C$29) | I583: 0.99361836 | J583: 0.61296544 | K583: =IF(NOT(AND(PAINEL_PESOS!$D$12="OK - 100%",PAINEL_PESOS!$F$20="OK - 100%",PAINEL_PESOS!$F$24="OK - 100%",PAINEL_PESOS!$F$27="OK - 100%",PAINEL_PESOS!$F$30="OK - 100%")),"", (E583*PAINEL_PESOS!$B$7+F583*PAINEL_PESOS!$B$8+G583*PAINEL_PESOS!$B$9+H583*PAINEL_PESOS!$B$10)*I583) | L583: =IF(K583="","",K583-J583) | M583: =IF(L583="","",ABS(L583)) | N583: 0.2 | O583: 1 | P583: 0.26800422 | Q583: 0.96591873 | R583: 0.19890523 | S583: 0.99994075 | T583: 0.99255697 | U583: 0.74982938 | V583: 0.42612354 | W583: 0.39399958 | X583: 0.68736901
A584: 2107803 | B584: Parnarama | C584: MA | D584: REGIÃO NORDESTE | E584: =SUMPRODUCT(N584:Q584,PAINEL_PESOS!$C$16:$C$19) | F584: =SUMPRODUCT(R584:T584,PAINEL_PESOS!$C$21:$C$23) | G584: =SUMPRODUCT(U584:V584,PAINEL_PESOS!$C$25:$C$26) | H584: =SUMPRODUCT(W584:X584,PAINEL_PESOS!$C$28:$C$29) | I584: 0.99467406 | J584: 0.68352176 | K584: =IF(NOT(AND(PAINEL_PESOS!$D$12="OK - 100%",PAINEL_PESOS!$F$20="OK - 100%",PAINEL_PESOS!$F$24="OK - 100%",PAINEL_PESOS!$F$27="OK - 100%",PAINEL_PESOS!$F$30="OK - 100%")),"", (E584*PAINEL_PESOS!$B$7+F584*PAINEL_PESOS!$B$8+G584*PAINEL_PESOS!$B$9+H584*PAINEL_PESOS!$B$10)*I584) | L584: =IF(K584="","",K584-J584) | M584: =IF(L584="","",ABS(L584)) | N584: 0.2 | O584: 1 | P584: 1 | Q584: 0.97999175 | R584: 0.25489891 | S584: 0.99998874 | T584: 0.98740919 | U584: 0.74335739 | V584: 0.60304564 | W584: 0.40712132 | X584: 0.65906842
A585: 2107902 | B585: Passagem Franca | C585: MA | D585: REGIÃO NORDESTE | E585: =SUMPRODUCT(N585:Q585,PAINEL_PESOS!$C$16:$C$19) | F585: =SUMPRODUCT(R585:T585,PAINEL_PESOS!$C$21:$C$23) | G585: =SUMPRODUCT(U585:V585,PAINEL_PESOS!$C$25:$C$26) | H585: =SUMPRODUCT(W585:X585,PAINEL_PESOS!$C$28:$C$29) | I585: 0.99707547 | J585: 0.68078412 | K585: =IF(NOT(AND(PAINEL_PESOS!$D$12="OK - 100%",PAINEL_PESOS!$F$20="OK - 100%",PAINEL_PESOS!$F$24="OK - 100%",PAINEL_PESOS!$F$27="OK - 100%",PAINEL_PESOS!$F$30="OK - 100%")),"", (E585*PAINEL_PESOS!$B$7+F585*PAINEL_PESOS!$B$8+G585*PAINEL_PESOS!$B$9+H585*PAINEL_PESOS!$B$10)*I585) | L585: =IF(K585="","",K585-J585) | M585: =IF(L585="","",ABS(L585)) | N585: 0.2 | O585: 1 | P585: 1 | Q585: 0.98549823 | R585: 0.1974256 | S585: 0.99997819 | T585: 0.99582784 | U585: 0.75092466 | V585: 0.57503373 | W585: 0.39394373 | X585: 0.68744183
A586: 2108009 | B586: Pastos Bons | C586: MA | D586: REGIÃO NORDESTE | E586: =SUMPRODUCT(N586:Q586,PAINEL_PESOS!$C$16:$C$19) | F586: =SUMPRODUCT(R586:T586,PAINEL_PESOS!$C$21:$C$23) | G586: =SUMPRODUCT(U586:V586,PAINEL_PESOS!$C$25:$C$26) | H586: =SUMPRODUCT(W586:X586,PAINEL_PESOS!$C$28:$C$29) | I586: 0.99712844 | J586: 0.72357903 | K586: =IF(NOT(AND(PAINEL_PESOS!$D$12="OK - 100%",PAINEL_PESOS!$F$20="OK - 100%",PAINEL_PESOS!$F$24="OK - 100%",PAINEL_PESOS!$F$27="OK - 100%",PAINEL_PESOS!$F$30="OK - 100%")),"", (E586*PAINEL_PESOS!$B$7+F586*PAINEL_PESOS!$B$8+G586*PAINEL_PESOS!$B$9+H586*PAINEL_PESOS!$B$10)*I586) | L586: =IF(K586="","",K586-J586) | M586: =IF(L586="","",ABS(L586)) | N586: 1 | O586: 0.9727 | P586: 0.99883844 | Q586: 0.98640155 | R586: 0.23909572 | S586: 0.99991604 | T586: 0.99546401 | U586: 0.77285152 | V586: 0.42126511 | W586: 0.42338593 | X586: 0.71917947
A587: 2108058 | B587: Paulino Neves | C587: MA | D587: REGIÃO NORDESTE | E587: =SUMPRODUCT(N587:Q587,PAINEL_PESOS!$C$16:$C$19) | F587: =SUMPRODUCT(R587:T587,PAINEL_PESOS!$C$21:$C$23) | G587: =SUMPRODUCT(U587:V587,PAINEL_PESOS!$C$25:$C$26) | H587: =SUMPRODUCT(W587:X587,PAINEL_PESOS!$C$28:$C$29) | I587: 0.99793095 | J587: 0.62539792 | K587: =IF(NOT(AND(PAINEL_PESOS!$D$12="OK - 100%",PAINEL_PESOS!$F$20="OK - 100%",PAINEL_PESOS!$F$24="OK - 100%",PAINEL_PESOS!$F$27="OK - 100%",PAINEL_PESOS!$F$30="OK - 100%")),"", (E587*PAINEL_PESOS!$B$7+F587*PAINEL_PESOS!$B$8+G587*PAINEL_PESOS!$B$9+H587*PAINEL_PESOS!$B$10)*I587) | L587: =IF(K587="","",K587-J587) | M587: =IF(L587="","",ABS(L587)) | N587: 0.2 | O587: 1 | P587: 0.18627244 | Q587: 0.99047579 | R587: 0.17204611 | S587: 1 | T587: 0.99650491 | U587: 0.72962764 | V587: 0.56181792 | W587: 0.50432136 | X587: 0.58371491
A588: 2108108 | B588: Paulo Ramos | C588: MA | D588: REGIÃO NORDESTE | E588: =SUMPRODUCT(N588:Q588,PAINEL_PESOS!$C$16:$C$19) | F588: =SUMPRODUCT(R588:T588,PAINEL_PESOS!$C$21:$C$23) | G588: =SUMPRODUCT(U588:V588,PAINEL_PESOS!$C$25:$C$26) | H588: =SUMPRODUCT(W588:X588,PAINEL_PESOS!$C$28:$C$29) | I588: 0.99293204 | J588: 0.54350155 | K588: =IF(NOT(AND(PAINEL_PESOS!$D$12="OK - 100%",PAINEL_PESOS!$F$20="OK - 100%",PAINEL_PESOS!$F$24="OK - 100%",PAINEL_PESOS!$F$27="OK - 100%",PAINEL_PESOS!$F$30="OK - 100%")),"", (E588*PAINEL_PESOS!$B$7+F588*PAINEL_PESOS!$B$8+G588*PAINEL_PESOS!$B$9+H588*PAINEL_PESOS!$B$10)*I588) | L588: =IF(K588="","",K588-J588) | M588: =IF(L588="","",ABS(L588)) | N588: 0.2 | O588: 0.1884 | P588: 0.11414995 | Q588: 0.96745123 | R588: 0.21921157 | S588: 0.9999822 | T588: 0.98769885 | U588: 0.29859014 | V588: 0.59510736 | W588: 0.51947962 | X588: 0.75952325
A589: 2108207 | B589: Pedreiras | C589: MA | D589: REGIÃO NORDESTE | E589: =SUMPRODUCT(N589:Q589,PAINEL_PESOS!$C$16:$C$19) | F589: =SUMPRODUCT(R589:T589,PAINEL_PESOS!$C$21:$C$23) | G589: =SUMPRODUCT(U589:V589,PAINEL_PESOS!$C$25:$C$26) | H589: =SUMPRODUCT(W589:X589,PAINEL_PESOS!$C$28:$C$29) | I589: 0.95120752 | J589: 0.59662982 | K589: =IF(NOT(AND(PAINEL_PESOS!$D$12="OK - 100%",PAINEL_PESOS!$F$20="OK - 100%",PAINEL_PESOS!$F$24="OK - 100%",PAINEL_PESOS!$F$27="OK - 100%",PAINEL_PESOS!$F$30="OK - 100%")),"", (E589*PAINEL_PESOS!$B$7+F589*PAINEL_PESOS!$B$8+G589*PAINEL_PESOS!$B$9+H589*PAINEL_PESOS!$B$10)*I589) | L589: =IF(K589="","",K589-J589) | M589: =IF(L589="","",ABS(L589)) | N589: 0.4 | O589: 0.979 | P589: 0.22903907 | Q589: 0.7310764 | R589: 0.32783343 | S589: 0.99474203 | T589: 0.93273751 | U589: 0.52883748 | V589: 0.58829067 | W589: 0.51452088 | X589: 0.71312432
A590: 2108256 | B590: Pedro do Rosário | C590: MA | D590: REGIÃO NORDESTE | E590: =SUMPRODUCT(N590:Q590,PAINEL_PESOS!$C$16:$C$19) | F590: =SUMPRODUCT(R590:T590,PAINEL_PESOS!$C$21:$C$23) | G590: =SUMPRODUCT(U590:V590,PAINEL_PESOS!$C$25:$C$26) | H590: =SUMPRODUCT(W590:X590,PAINEL_PESOS!$C$28:$C$29) | I590: 0.99410785 | J590: 0.68077536 | K590: =IF(NOT(AND(PAINEL_PESOS!$D$12="OK - 100%",PAINEL_PESOS!$F$20="OK - 100%",PAINEL_PESOS!$F$24="OK - 100%",PAINEL_PESOS!$F$27="OK - 100%",PAINEL_PESOS!$F$30="OK - 100%")),"", (E590*PAINEL_PESOS!$B$7+F590*PAINEL_PESOS!$B$8+G590*PAINEL_PESOS!$B$9+H590*PAINEL_PESOS!$B$10)*I590) | L590: =IF(K590="","",K590-J590) | M590: =IF(L590="","",ABS(L590)) | N590: 0.2 | O590: 1 | P590: 1 | Q590: 0.96865665 | R590: 0.20557966 | S590: 1 | T590: 0.99303405 | U590: 0.36359801 | V590: 0.57726833 | W590: 0.69428523 | X590: 0.79326059
A591: 2108306 | B591: Penalva | C591: MA | D591: REGIÃO NORDESTE | E591: =SUMPRODUCT(N591:Q591,PAINEL_PESOS!$C$16:$C$19) | F591: =SUMPRODUCT(R591:T591,PAINEL_PESOS!$C$21:$C$23) | G591: =SUMPRODUCT(U591:V591,PAINEL_PESOS!$C$25:$C$26) | H591: =SUMPRODUCT(W591:X591,PAINEL_PESOS!$C$28:$C$29) | I591: 0.9785051 | J591: 0.57147829 | K591: =IF(NOT(AND(PAINEL_PESOS!$D$12="OK - 100%",PAINEL_PESOS!$F$20="OK - 100%",PAINEL_PESOS!$F$24="OK - 100%",PAINEL_PESOS!$F$27="OK - 100%",PAINEL_PESOS!$F$30="OK - 100%")),"", (E591*PAINEL_PESOS!$B$7+F591*PAINEL_PESOS!$B$8+G591*PAINEL_PESOS!$B$9+H591*PAINEL_PESOS!$B$10)*I591) | L591: =IF(K591="","",K591-J591) | M591: =IF(L591="","",ABS(L591)) | N591: 0.2 | O591: 0.6226 | P591: 0.19831045 | Q591: 0.86718098 | R591: 0.23633153 | S591: 0.99995579 | T591: 0.98736048 | U591: 0.25428172 | V591: 0.58175789 | W591: 0.59594845 | X591: 0.81379035
A592: 2108405 | B592: Peri Mirim | C592: MA | D592: REGIÃO NORDESTE | E592: =SUMPRODUCT(N592:Q592,PAINEL_PESOS!$C$16:$C$19) | F592: =SUMPRODUCT(R592:T592,PAINEL_PESOS!$C$21:$C$23) | G592: =SUMPRODUCT(U592:V592,PAINEL_PESOS!$C$25:$C$26) | H592: =SUMPRODUCT(W592:X592,PAINEL_PESOS!$C$28:$C$29) | I592: 0.98778112 | J592: 0.61107623 | K592: =IF(NOT(AND(PAINEL_PESOS!$D$12="OK - 100%",PAINEL_PESOS!$F$20="OK - 100%",PAINEL_PESOS!$F$24="OK - 100%",PAINEL_PESOS!$F$27="OK - 100%",PAINEL_PESOS!$F$30="OK - 100%")),"", (E592*PAINEL_PESOS!$B$7+F592*PAINEL_PESOS!$B$8+G592*PAINEL_PESOS!$B$9+H592*PAINEL_PESOS!$B$10)*I592) | L592: =IF(K592="","",K592-J592) | M592: =IF(L592="","",ABS(L592)) | N592: 0.2 | O592: 0.5 | P592: 0.31351637 | Q592: 0.92567034 | R592: 0.13807153 | S592: 0.99999096 | T592: 0.99240228 | U592: 0.54416509 | V592: 0.57556676 | W592: 0.72103664 | X592: 0.71841039
A593: 2108454 | B593: Peritoró | C593: MA | D593: REGIÃO NORDESTE | E593: =SUMPRODUCT(N593:Q593,PAINEL_PESOS!$C$16:$C$19) | F593: =SUMPRODUCT(R593:T593,PAINEL_PESOS!$C$21:$C$23) | G593: =SUMPRODUCT(U593:V593,PAINEL_PESOS!$C$25:$C$26) | H593: =SUMPRODUCT(W593:X593,PAINEL_PESOS!$C$28:$C$29) | I593: 0.99118258 | J593: 0.60172037 | K593: =IF(NOT(AND(PAINEL_PESOS!$D$12="OK - 100%",PAINEL_PESOS!$F$20="OK - 100%",PAINEL_PESOS!$F$24="OK - 100%",PAINEL_PESOS!$F$27="OK - 100%",PAINEL_PESOS!$F$30="OK - 100%")),"", (E593*PAINEL_PESOS!$B$7+F593*PAINEL_PESOS!$B$8+G593*PAINEL_PESOS!$B$9+H593*PAINEL_PESOS!$B$10)*I593) | L593: =IF(K593="","",K593-J593) | M593: =IF(L593="","",ABS(L593)) | N593: 0.2 | O593: 0.767 | P593: 0.18162619 | Q593: 0.95938768 | R593: 0.22508757 | S593: 1 | T593: 0.98446208 | U593: 0.54775098 | V593: 0.58598433 | W593: 0.49820848 | X593: 0.69760166
... A606: 2109403 | B606: Primeira Cruz | C606: MA | D606: REGIÃO NORDESTE | E606: =SUMPRODUCT(N606:Q606,PAINEL_PESOS!$C$16:$C$19) | F606: =SUMPRODUCT(R606:T606,PAINEL_PESOS!$C$21:$C$23) | G606: =SUMPRODUCT(U606:V606,PAINEL_PESOS!$C$25:$C$26) | H606: =SUMPRODUCT(W606:X606,PAINEL_PESOS!$C$28:$C$29) | I606: 0.99842273 | J606: 0.60556363 | K606: =IF(NOT(AND(PAINEL_PESOS!$D$12="OK - 100%",PAINEL_PESOS!$F$20="OK - 100%",PAINEL_PESOS!$F$24="OK - 100%",PAINEL_PESOS!$F$27="OK - 100%",PAINEL_PESOS!$F$30="OK - 100%")),"", (E606*PAINEL_PESOS!$B$7+F606*PAINEL_PESOS!$B$8+G606*PAINEL_PESOS!$B$9+H606*PAINEL_PESOS!$B$10)*I606) | L606: =IF(K606="","",K606-J606) | M606: =IF(L606="","",ABS(L606)) | N606: 0.2 | O606: 1 | P606: 0.19007392 | Q606: 0.99104862 | R606: 0.14662114 | S606: 1 | T606: 0.99861793 | U606: 0.45838326 | V606: 0.56591783 | W606: 0.56375588 | X606: 0.64338459
A607: 2109452 | B607: Raposa | C607: MA | D607: REGIÃO NORDESTE | E607: =SUMPRODUCT(N607:Q607,PAINEL_PESOS!$C$16:$C$19) | F607: =SUMPRODUCT(R607:T607,PAINEL_PESOS!$C$21:$C$23) | G607: =SUMPRODUCT(U607:V607,PAINEL_PESOS!$C$25:$C$26) | H607: =SUMPRODUCT(W607:X607,PAINEL_PESOS!$C$28:$C$29) | I607: 0.89706411 | K607: =IF(NOT(AND(PAINEL_PESOS!$D$12="OK - 100%",PAINEL_PESOS!$F$20="OK - 100%",PAINEL_PESOS!$F$24="OK - 100%",PAINEL_PESOS!$F$27="OK - 100%",PAINEL_PESOS!$F$30="OK - 100%")),"", (E607*PAINEL_PESOS!$B$7+F607*PAINEL_PESOS!$B$8+G607*PAINEL_PESOS!$B$9+H607*PAINEL_PESOS!$B$10)*I607) | L607: =IF(K607="","",K607-J607) | M607: =IF(L607="","",ABS(L607)) | N607: 0.2 | O607: 1 | P607: 1 | Q607: 0.43917279 | R607: 0.25472117 | S607: 0.97116298 | T607: 0.79541058 | V607: 0.56742833
A608: 2109502 | B608: Riachão | C608: MA | D608: REGIÃO NORDESTE | E608: =SUMPRODUCT(N608:Q608,PAINEL_PESOS!$C$16:$C$19) | F608: =SUMPRODUCT(R608:T608,PAINEL_PESOS!$C$21:$C$23) | G608: =SUMPRODUCT(U608:V608,PAINEL_PESOS!$C$25:$C$26) | H608: =SUMPRODUCT(W608:X608,PAINEL_PESOS!$C$28:$C$29) | I608: 0.99890747 | J608: 0.71443626 | K608: =IF(NOT(AND(PAINEL_PESOS!$D$12="OK - 100%",PAINEL_PESOS!$F$20="OK - 100%",PAINEL_PESOS!$F$24="OK - 100%",PAINEL_PESOS!$F$27="OK - 100%",PAINEL_PESOS!$F$30="OK - 100%")),"", (E608*PAINEL_PESOS!$B$7+F608*PAINEL_PESOS!$B$8+G608*PAINEL_PESOS!$B$9+H608*PAINEL_PESOS!$B$10)*I608) | L608: =IF(K608="","",K608-J608) | M608: =IF(L608="","",ABS(L608)) | N608: 1 | O608: 0.9524 | P608: 0.45987328 | Q608: 0.9993023 | R608: 0.31015479 | S608: 0.99999452 | T608: 0.99493838 | U608: 0.53138778 | V608: 0.57323474 | W608: 0.5782058 | X608: 0.79640003
A609: 2109551 | B609: Ribamar Fiquene | C609: MA | D609: REGIÃO NORDESTE | E609: =SUMPRODUCT(N609:Q609,PAINEL_PESOS!$C$16:$C$19) | F609: =SUMPRODUCT(R609:T609,PAINEL_PESOS!$C$21:$C$23) | G609: =SUMPRODUCT(U609:V609,PAINEL_PESOS!$C$25:$C$26) | H609: =SUMPRODUCT(W609:X609,PAINEL_PESOS!$C$28:$C$29) | I609: 0.99350307 | J609: 0.71381522 | K609: =IF(NOT(AND(PAINEL_PESOS!$D$12="OK - 100%",PAINEL_PESOS!$F$20="OK - 100%",PAINEL_PESOS!$F$24="OK - 100%",PAINEL_PESOS!$F$27="OK - 100%",PAINEL_PESOS!$F$30="OK - 100%")),"", (E609*PAINEL_PESOS!$B$7+F609*PAINEL_PESOS!$B$8+G609*PAINEL_PESOS!$B$9+H609*PAINEL_PESOS!$B$10)*I609) | L609: =IF(K609="","",K609-J609) | M609: =IF(L609="","",ABS(L609)) | N609: 0.2 | O609: 1 | P609: 1 | Q609: 0.996496 | R609: 0.16654936 | S609: 0.99998991 | T609: 0.96929159 | U609: 0.58978193 | V609: 0.5658851 | W609: 0.7535055 | X609: 0.81655746
A610: 2109601 | B610: Rosário | C610: MA | D610: REGIÃO NORDESTE | E610: =SUMPRODUCT(N610:Q610,PAINEL_PESOS!$C$16:$C$19) | F610: =SUMPRODUCT(R610:T610,PAINEL_PESOS!$C$21:$C$23) | G610: =SUMPRODUCT(U610:V610,PAINEL_PESOS!$C$25:$C$26) | H610: =SUMPRODUCT(W610:X610,PAINEL_PESOS!$C$28:$C$29) | I610: 0.9829046 | J610: 0.67453399 | K610: =IF(NOT(AND(PAINEL_PESOS!$D$12="OK - 100%",PAINEL_PESOS!$F$20="OK - 100%",PAINEL_PESOS!$F$24="OK - 100%",PAINEL_PESOS!$F$27="OK - 100%",PAINEL_PESOS!$F$30="OK - 100%")),"", (E610*PAINEL_PESOS!$B$7+F610*PAINEL_PESOS!$B$8+G610*PAINEL_PESOS!$B$9+H610*PAINEL_PESOS!$B$10)*I610) | L610: =IF(K610="","",K610-J610) | M610: =IF(L610="","",ABS(L610)) | N610: 0.4 | O610: 0.9653 | P610: 0.58817318 | Q610: 0.89571435 | R610: 0.28433976 | S610: 0.99854984 | T610: 0.99212042 | U610: 0.67032312 | V610: 0.57493608 | W610: 0.60422533 | X610: 0.69937619
A611: 2109700 | B611: Sambaíba | C611: MA | D611: REGIÃO NORDESTE | E611: =SUMPRODUCT(N611:Q611,PAINEL_PESOS!$C$16:$C$19) | F611: =SUMPRODUCT(R611:T611,PAINEL_PESOS!$C$21:$C$23) | G611: =SUMPRODUCT(U611:V611,PAINEL_PESOS!$C$25:$C$26) | H611: =SUMPRODUCT(W611:X611,PAINEL_PESOS!$C$28:$C$29) | I611: 0.99974115 | J611: 0.66204338 | K611: =IF(NOT(AND(PAINEL_PESOS!$D$12="OK - 100%",PAINEL_PESOS!$F$20="OK - 100%",PAINEL_PESOS!$F$24="OK - 100%",PAINEL_PESOS!$F$27="OK - 100%",PAINEL_PESOS!$F$30="OK - 100%")),"", (E611*PAINEL_PESOS!$B$7+F611*PAINEL_PESOS!$B$8+G611*PAINEL_PESOS!$B$9+H611*PAINEL_PESOS!$B$10)*I611) | L611: =IF(K611="","",K611-J611) | M611: =IF(L611="","",ABS(L611)) | N611: 0.4 | O611: 0.7468 | P611: 0.26420275 | Q611: 0.99928331 | R611: 0.26679035 | S611: 0.99999162 | T611: 0.99921605 | U611: 0.65364708 | V611: 0.50405244 | W611: 0.63033233 | X611: 0.79387815
A612: 2109759 | B612: Santa Filomena do Maranhão | C612: MA | D612: REGIÃO NORDESTE | E612: =SUMPRODUCT(N612:Q612,PAINEL_PESOS!$C$16:$C$19) | F612: =SUMPRODUCT(R612:T612,PAINEL_PESOS!$C$21:$C$23) | G612: =SUMPRODUCT(U612:V612,PAINEL_PESOS!$C$25:$C$26) | H612: =SUMPRODUCT(W612:X612,PAINEL_PESOS!$C$28:$C$29) | I612: 0.99788736 | J612: 0.61264297 | K612: =IF(NOT(AND(PAINEL_PESOS!$D$12="OK - 100%",PAINEL_PESOS!$F$20="OK - 100%",PAINEL_PESOS!$F$24="OK - 100%",PAINEL_PESOS!$F$27="OK - 100%",PAINEL_PESOS!$F$30="OK - 100%")),"", (E612*PAINEL_PESOS!$B$7+F612*PAINEL_PESOS!$B$8+G612*PAINEL_PESOS!$B$9+H612*PAINEL_PESOS!$B$10)*I612) | L612: =IF(K612="","",K612-J612) | M612: =IF(L612="","",ABS(L612)) | N612: 0.2 | O612: 1 | P612: 0.45681098 | Q612: 0.99279074 | R612: 0.09811131 | S612: 1 | T612: 0.99454315 | U612: 0.42791487 | V612: 0.62813652 | W612: 0.43455415 | X612: 0.70101068
A613: 2109809 | B613: Santa Helena | C613: MA | D613: REGIÃO NORDESTE | E613: =SUMPRODUCT(N613:Q613,PAINEL_PESOS!$C$16:$C$19) | F613: =SUMPRODUCT(R613:T613,PAINEL_PESOS!$C$21:$C$23) | G613: =SUMPRODUCT(U613:V613,PAINEL_PESOS!$C$25:$C$26) | H613: =SUMPRODUCT(W613:X613,PAINEL_PESOS!$C$28:$C$29) | I613: 0.99329298 | J613: 0.7014769 | K613: =IF(NOT(AND(PAINEL_PESOS!$D$12="OK - 100%",PAINEL_PESOS!$F$20="OK - 100%",PAINEL_PESOS!$F$24="OK - 100%",PAINEL_PESOS!$F$27="OK - 100%",PAINEL_PESOS!$F$30="OK - 100%")),"", (E613*PAINEL_PESOS!$B$7+F613*PAINEL_PESOS!$B$8+G613*PAINEL_PESOS!$B$9+H613*PAINEL_PESOS!$B$10)*I613) | L613: =IF(K613="","",K613-J613) | M613: =IF(L613="","",ABS(L613)) | N613: 0.2 | O613: 1 | P613: 1 | Q613: 0.97012124 | R613: 0.27715296 | S613: 0.99998352 | T613: 0.98762647 | U613: 0.42909542 | V613: 0.57611705 | W613: 0.78274306 | X613: 0.76684983
A614: 2109908 | B614: Santa Inês | C614: MA | D614: REGIÃO NORDESTE | E614: =SUMPRODUCT(N614:Q614,PAINEL_PESOS!$C$16:$C$19) | F614: =SUMPRODUCT(R614:T614,PAINEL_PESOS!$C$21:$C$23) | G614: =SUMPRODUCT(U614:V614,PAINEL_PESOS!$C$25:$C$26) | H614: =SUMPRODUCT(W614:X614,PAINEL_PESOS!$C$28:$C$29) | I614: 0.94388749 | J614: 0.56327745 | K614: =IF(NOT(AND(PAINEL_PESOS!$D$12="OK - 100%",PAINEL_PESOS!$F$20="OK - 100%",PAINEL_PESOS!$F$24="OK - 100%",PAINEL_PESOS!$F$27="OK - 100%",PAINEL_PESOS!$F$30="OK - 100%")),"", (E614*PAINEL_PESOS!$B$7+F614*PAINEL_PESOS!$B$8+G614*PAINEL_PESOS!$B$9+H614*PAINEL_PESOS!$B$10)*I614) | L614: =IF(K614="","",K614-J614) | M614: =IF(L614="","",ABS(L614)) | N614: 0.2 | O614: 0.8952 | P614: 0.36504752 | Q614: 0.6538264 | R614: 0.40244306 | S614: 0.99680804 | T614: 0.9564429 | U614: 0.26009658 | V614: 0.58293859 | W614: 0.53160723 | X614: 0.77196471
A615: 2110005 | B615: Santa Luzia | C615: MA | D615: REGIÃO NORDESTE | E615: =SUMPRODUCT(N615:Q615,PAINEL_PESOS!$C$16:$C$19) | F615: =SUMPRODUCT(R615:T615,PAINEL_PESOS!$C$21:$C$23) | G615: =SUMPRODUCT(U615:V615,PAINEL_PESOS!$C$25:$C$26) | H615: =SUMPRODUCT(W615:X615,PAINEL_PESOS!$C$28:$C$29) | I615: 0.99147884 | J615: 0.68287826 | K615: =IF(NOT(AND(PAINEL_PESOS!$D$12="OK - 100%",PAINEL_PESOS!$F$20="OK - 100%",PAINEL_PESOS!$F$24="OK - 100%",PAINEL_PESOS!$F$27="OK - 100%",PAINEL_PESOS!$F$30="OK - 100%")),"", (E615*PAINEL_PESOS!$B$7+F615*PAINEL_PESOS!$B$8+G615*PAINEL_PESOS!$B$9+H615*PAINEL_PESOS!$B$10)*I615) | L615: =IF(K615="","",K615-J615) | M615: =IF(L615="","",ABS(L615)) | N615: 1 | O615: 0.837 | P615: 0.4030623 | Q615: 0.97803903 | R615: 0.3439678 | S615: 0.99994363 | T615: 0.97207874 | U615: 0.47555704 | V615: 0.58555662 | W615: 0.59657338 | X615: 0.69924635
A616: 2110039 | B616: Santa Luzia do Paruá | C616: MA | D616: REGIÃO NORDESTE | E616: =SUMPRODUCT(N616:Q616,PAINEL_PESOS!$C$16:$C$19) | F616: =SUMPRODUCT(R616:T616,PAINEL_PESOS!$C$21:$C$23) | G616: =SUMPRODUCT(U616:V616,PAINEL_PESOS!$C$25:$C$26) | H616: =SUMPRODUCT(W616:X616,PAINEL_PESOS!$C$28:$C$29) | I616: 0.97618904 | J616: 0.66017584 | K616: =IF(NOT(AND(PAINEL_PESOS!$D$12="OK - 100%",PAINEL_PESOS!$F$20="OK - 100%",PAINEL_PESOS!$F$24="OK - 100%",PAINEL_PESOS!$F$27="OK - 100%",PAINEL_PESOS!$F$30="OK - 100%")),"", (E616*PAINEL_PESOS!$B$7+F616*PAINEL_PESOS!$B$8+G616*PAINEL_PESOS!$B$9+H616*PAINEL_PESOS!$B$10)*I616) | L616: =IF(K616="","",K616-J616) | M616: =IF(L616="","",ABS(L616)) | N616: 0.2 | O616: 0.9211 | P616: 0.75385428 | Q616: 0.93223123 | R616: 0.25513741 | S616: 0.99998024 | T616: 0.92235418 | U616: 0.26848039 | V616: 0.57633679 | W616: 0.8904561 | X616: 0.81971551
A617: 2110104 | B617: Santa Quitéria do Maranhão | C617: MA | D617: REGIÃO NORDESTE | E617: =SUMPRODUCT(N617:Q617,PAINEL_PESOS!$C$16:$C$19) | F617: =SUMPRODUCT(R617:T617,PAINEL_PESOS!$C$21:$C$23) | G617: =SUMPRODUCT(U617:V617,PAINEL_PESOS!$C$25:$C$26) | H617: =SUMPRODUCT(W617:X617,PAINEL_PESOS!$C$28:$C$29) | I617: 0.99588247 | J617: 0.65706314 | K617: =IF(NOT(AND(PAINEL_PESOS!$D$12="OK - 100%",PAINEL_PESOS!$F$20="OK - 100%",PAINEL_PESOS!$F$24="OK - 100%",PAINEL_PESOS!$F$27="OK - 100%",PAINEL_PESOS!$F$30="OK - 100%")),"", (E617*PAINEL_PESOS!$B$7+F617*PAINEL_PESOS!$B$8+G617*PAINEL_PESOS!$B$9+H617*PAINEL_PESOS!$B$10)*I617) | L617: =IF(K617="","",K617-J617) | M617: =IF(L617="","",ABS(L617)) | N617: 0.4 | O617: 1 | P617: 0.32787751 | Q617: 0.97526656 | R617: 0.25729904 | S617: 0.99998132 | T617: 0.99737649 | U617: 0.73809107 | V617: 0.57199744 | W617: 0.53558179 | X617: 0.5778915
A618: 2110203 | B618: Santa Rita | C618: MA | D618: REGIÃO NORDESTE | E618: =SUMPRODUCT(N618:Q618,PAINEL_PESOS!$C$16:$C$19) | F618: =SUMPRODUCT(R618:T618,PAINEL_PESOS!$C$21:$C$23) | G618: =SUMPRODUCT(U618:V618,PAINEL_PESOS!$C$25:$C$26) | H618: =SUMPRODUCT(W618:X618,PAINEL_PESOS!$C$28:$C$29) | I618: 0.97948329 | J618: 0.65580673 | K618: =IF(NOT(AND(PAINEL_PESOS!$D$12="OK - 100%",PAINEL_PESOS!$F$20="OK - 100%",PAINEL_PESOS!$F$24="OK - 100%",PAINEL_PESOS!$F$27="OK - 100%",PAINEL_PESOS!$F$30="OK - 100%")),"", (E618*PAINEL_PESOS!$B$7+F618*PAINEL_PESOS!$B$8+G618*PAINEL_PESOS!$B$9+H618*PAINEL_PESOS!$B$10)*I618) | L618: =IF(K618="","",K618-J618) | M618: =IF(L618="","",ABS(L618)) | N618: 0.2 | O618: 1 | P618: 0.94350581 | Q618: 0.89163036 | R618: 0.25060996 | S618: 0.99816615 | T618: 0.97332556 | U618: 0.46432731 | V618: 0.58239534 | W618: 0.61546092 | X618: 0.69519578
...

Sheet RESULTADOS_OTTO_N4
A1: wts_pk | B1: Humana ponderada | C1: Econômica ponderada | D1: Ecossistêmica ponderada | E1: Resiliência ponderada | F1: Fator Q95 | G1: ISH Beta 25/25/25/25 | H1: ISH com pesos escolhidos | I1: Diferença vs Beta | J1: Diferença absoluta | K1: Abastecimento | L1: Potabilidade | M1: Perdas_inv | N1: Seg_humana_hidrica | O1: PIB | P1: Seg_industrial | Q1: Seg_agro | R1: Cobertura_florestal | S1: DBO_inv | T1: SPI12 | U1: CV_pluv_inv
A2: 1349205 | B2: =SUMPRODUCT(K2:N2,PAINEL_PESOS!$C$16:$C$19) | C2: =SUMPRODUCT(O2:Q2,PAINEL_PESOS!$C$21:$C$23) | D2: =SUMPRODUCT(R2:S2,PAINEL_PESOS!$C$25:$C$26) | E2: =SUMPRODUCT(T2:U2,PAINEL_PESOS!$C$28:$C$29) | F2: 0.99989072 | G2: 0.65435025 | H2: =IF(NOT(AND(PAINEL_PESOS!$D$12="OK - 100%",PAINEL_PESOS!$F$20="OK - 100%",PAINEL_PESOS!$F$24="OK - 100%",PAINEL_PESOS!$F$27="OK - 100%",PAINEL_PESOS!$F$30="OK - 100%")),"", (B2*PAINEL_PESOS!$B$7+C2*PAINEL_PESOS!$B$8+D2*PAINEL_PESOS!$B$9+E2*PAINEL_PESOS!$B$10)*F2) | I2: =IF(H2="","",H2-G2) | J2: =IF(I2="","",ABS(I2)) | K2: 0.9876203 | L2: 0 | M2: 0.55256653 | N2: 0.99983295 | O2: 0.44654707 | P2: 0.99930162 | Q2: 0.9996947 | R2: 0.72930164 | S2: 0.25018289 | T2: 0.41936848 | U2: 0.936149
A3: 1349345 | B3: =SUMPRODUCT(K3:N3,PAINEL_PESOS!$C$16:$C$19) | C3: =SUMPRODUCT(O3:Q3,PAINEL_PESOS!$C$21:$C$23) | D3: =SUMPRODUCT(R3:S3,PAINEL_PESOS!$C$25:$C$26) | E3: =SUMPRODUCT(T3:U3,PAINEL_PESOS!$C$28:$C$29) | F3: 0.99831672 | G3: 0.60688235 | H3: =IF(NOT(AND(PAINEL_PESOS!$D$12="OK - 100%",PAINEL_PESOS!$F$20="OK - 100%",PAINEL_PESOS!$F$24="OK - 100%",PAINEL_PESOS!$F$27="OK - 100%",PAINEL_PESOS!$F$30="OK - 100%")),"", (B3*PAINEL_PESOS!$B$7+C3*PAINEL_PESOS!$B$8+D3*PAINEL_PESOS!$B$9+E3*PAINEL_PESOS!$B$10)*F3) | I3: =IF(H3="","",H3-G3) | J3: =IF(I3="","",ABS(I3)) | K3: 0.58088076 | L3: 0.49051768 | M3: 0.56076582 | N3: 0.99965466 | O3: 0.30519573 | P3: 0.99993715 | Q3: 0.9920749 | R3: 0.49059402 | S3: 0.080228626 | T3: 0.56538775 | U3: 0.87965332
A4: 1349346 | B4: =SUMPRODUCT(K4:N4,PAINEL_PESOS!$C$16:$C$19) | C4: =SUMPRODUCT(O4:Q4,PAINEL_PESOS!$C$21:$C$23) | D4: =SUMPRODUCT(R4:S4,PAINEL_PESOS!$C$25:$C$26) | E4: =SUMPRODUCT(T4:U4,PAINEL_PESOS!$C$28:$C$29) | F4: 0.99996365 | G4: 0.65073567 | H4: =IF(NOT(AND(PAINEL_PESOS!$D$12="OK - 100%",PAINEL_PESOS!$F$20="OK - 100%",PAINEL_PESOS!$F$24="OK - 100%",PAINEL_PESOS!$F$27="OK - 100%",PAINEL_PESOS!$F$30="OK - 100%")),"", (B4*PAINEL_PESOS!$B$7+C4*PAINEL_PESOS!$B$8+D4*PAINEL_PESOS!$B$9+E4*PAINEL_PESOS!$B$10)*F4) | I4: =IF(H4="","",H4-G4) | J4: =IF(I4="","",ABS(I4)) | K4: 1 | L4: 0.00040714488 | M4: 0.40302659 | N4: 0.99998774 | O4: 0.35030928 | P4: 0.99999989 | Q4: 0.99983407 | R4: 0.25119423 | S4: 0.31354681 | T4: 1 | U4: 0.87286063
A5: 1349347 | B5: =SUMPRODUCT(K5:N5,PAINEL_PESOS!$C$16:$C$19) | C5: =SUMPRODUCT(O5:Q5,PAINEL_PESOS!$C$21:$C$23) | D5: =SUMPRODUCT(R5:S5,PAINEL_PESOS!$C$25:$C$26) | E5: =SUMPRODUCT(T5:U5,PAINEL_PESOS!$C$28:$C$29) | F5: 0.99950632 | G5: 0.6457085 | H5: =IF(NOT(AND(PAINEL_PESOS!$D$12="OK - 100%",PAINEL_PESOS!$F$20="OK - 100%",PAINEL_PESOS!$F$24="OK - 100%",PAINEL_PESOS!$F$27="OK - 100%",PAINEL_PESOS!$F$30="OK - 100%")),"", (B5*PAINEL_PESOS!$B$7+C5*PAINEL_PESOS!$B$8+D5*PAINEL_PESOS!$B$9+E5*PAINEL_PESOS!$B$10)*F5) | I5: =IF(H5="","",H5-G5) | J5: =IF(I5="","",ABS(I5)) | K5: 0.89944563 | L5: 0.1360222 | M5: 0.51980136 | N5: 0.99955895 | O5: 0.38593899 | P5: 0.99958276 | Q5: 0.9979558 | R5: 0.3766196 | S5: 0.35561314 | T5: 0.67628311 | U5: 0.89330445
A6: 1349348 | B6: =SUMPRODUCT(K6:N6,PAINEL_PESOS!$C$16:$C$19) | C6: =SUMPRODUCT(O6:Q6,PAINEL_PESOS!$C$21:$C$23) | D6: =SUMPRODUCT(R6:S6,PAINEL_PESOS!$C$25:$C$26) | E6: =SUMPRODUCT(T6:U6,PAINEL_PESOS!$C$28:$C$29) | F6: 0.9995206 | G6: 0.64186229 | H6: =IF(NOT(AND(PAINEL_PESOS!$D$12="OK - 100%",PAINEL_PESOS!$F$20="OK - 100%",PAINEL_PESOS!$F$24="OK - 100%",PAINEL_PESOS!$F$27="OK - 100%",PAINEL_PESOS!$F$30="OK - 100%")),"", (B6*PAINEL_PESOS!$B$7+C6*PAINEL_PESOS!$B$8+D6*PAINEL_PESOS!$B$9+E6*PAINEL_PESOS!$B$10)*F6) | I6: =IF(H6="","",H6-G6) | J6: =IF(I6="","",ABS(I6)) | K6: 0.2 | L6: 0 | M6: 1 | N6: 0.99649505 | O6: 0.51122472 | P6: 0.99985004 | Q6: 0.999668 | R6: 0.54819324 | S6: 0.5487675 | T6: 0.37890314 | U6: 0.88942125
A7: 1349349 | B7: =SUMPRODUCT(K7:N7,PAINEL_PESOS!$C$16:$C$19) | C7: =SUMPRODUCT(O7:Q7,PAINEL_PESOS!$C$21:$C$23) | D7: =SUMPRODUCT(R7:S7,PAINEL_PESOS!$C$25:$C$26) | E7: =SUMPRODUCT(T7:U7,PAINEL_PESOS!$C$28:$C$29) | F7: 0.99971867 | G7: 0.69049285 | H7: =IF(NOT(AND(PAINEL_PESOS!$D$12="OK - 100%",PAINEL_PESOS!$F$20="OK - 100%",PAINEL_PESOS!$F$24="OK - 100%",PAINEL_PESOS!$F$27="OK - 100%",PAINEL_PESOS!$F$30="OK - 100%")),"", (B7*PAINEL_PESOS!$B$7+C7*PAINEL_PESOS!$B$8+D7*PAINEL_PESOS!$B$9+E7*PAINEL_PESOS!$B$10)*F7) | I7: =IF(H7="","",H7-G7) | J7: =IF(I7="","",ABS(I7)) | K7: 0.37898033 | L7: 0.92080564 | M7: 0.25047651 | N7: 0.99868952 | O7: 0.28236808 | P7: 0.99997326 | Q7: 0.99937709 | R7: 0.65125746 | S7: 0.5387896 | T7: 0.62697218 | U7: 0.91285643
A8: 1349350 | B8: =SUMPRODUCT(K8:N8,PAINEL_PESOS!$C$16:$C$19) | C8: =SUMPRODUCT(O8:Q8,PAINEL_PESOS!$C$21:$C$23) | D8: =SUMPRODUCT(R8:S8,PAINEL_PESOS!$C$25:$C$26) | E8: =SUMPRODUCT(T8:U8,PAINEL_PESOS!$C$28:$C$29) | F8: 0.99993783 | G8: 0.70134292 | H8: =IF(NOT(AND(PAINEL_PESOS!$D$12="OK - 100%",PAINEL_PESOS!$F$20="OK - 100%",PAINEL_PESOS!$F$24="OK - 100%",PAINEL_PESOS!$F$27="OK - 100%",PAINEL_PESOS!$F$30="OK - 100%")),"", (B8*PAINEL_PESOS!$B$7+C8*PAINEL_PESOS!$B$8+D8*PAINEL_PESOS!$B$9+E8*PAINEL_PESOS!$B$10)*F8) | I8: =IF(H8="","",H8-G8) | J8: =IF(I8="","",ABS(I8)) | K8: 0.41400329 | L8: 0.15065665 | M8: 0.87775663 | N8: 0.99959735 | O8: 0.22600327 | P8: 0.99998138 | Q8: 0.99992801 | R8: 0.95979667 | S8: 0.52453292 | T8: 0.55319724 | U8: 0.86861664
A9: 1349351 | B9: =SUMPRODUCT(K9:N9,PAINEL_PESOS!$C$16:$C$19) | C9: =SUMPRODUCT(O9:Q9,PAINEL_PESOS!$C$21:$C$23) | D9: =SUMPRODUCT(R9:S9,PAINEL_PESOS!$C$25:$C$26) | E9: =SUMPRODUCT(T9:U9,PAINEL_PESOS!$C$28:$C$29) | F9: 0.99998379 | G9: 0.74219274 | H9: =IF(NOT(AND(PAINEL_PESOS!$D$12="OK - 100%",PAINEL_PESOS!$F$20="OK - 100%",PAINEL_PESOS!$F$24="OK - 100%",PAINEL_PESOS!$F$27="OK - 100%",PAINEL_PESOS!$F$30="OK - 100%")),"", (B9*PAINEL_PESOS!$B$7+C9*PAINEL_PESOS!$B$8+D9*PAINEL_PESOS!$B$9+E9*PAINEL_PESOS!$B$10)*F9) | I9: =IF(H9="","",H9-G9) | J9: =IF(I9="","",ABS(I9)) | K9: 1 | L9: 0 | M9: 1 | N9: 0.99989913 | O9: 0.25088902 | P9: 0.99992692 | Q9: 0.99999195 | R9: 0.91496373 | S9: 0.53165339 | T9: 0.57273925 | U9: 0.91779366
A10: 1349352 | B10: =SUMPRODUCT(K10:N10,PAINEL_PESOS!$C$16:$C$19) | C10: =SUMPRODUCT(O10:Q10,PAINEL_PESOS!$C$21:$C$23) | D10: =SUMPRODUCT(R10:S10,PAINEL_PESOS!$C$25:$C$26) | E10: =SUMPRODUCT(T10:U10,PAINEL_PESOS!$C$28:$C$29) | F10: 0.99997571 | G10: 0.69394978 | H10: =IF(NOT(AND(PAINEL_PESOS!$D$12="OK - 100%",PAINEL_PESOS!$F$20="OK - 100%",PAINEL_PESOS!$F$24="OK - 100%",PAINEL_PESOS!$F$27="OK - 100%",PAINEL_PESOS!$F$30="OK - 100%")),"", (B10*PAINEL_PESOS!$B$7+C10*PAINEL_PESOS!$B$8+D10*PAINEL_PESOS!$B$9+E10*PAINEL_PESOS!$B$10)*F10) | I10: =IF(H10="","",H10-G10) | J10: =IF(I10="","",ABS(I10)) | K10: 0.45090327 | L10: 0 | M10: 0.99705429 | N10: 0.999846 | O10: 0.23150835 | P10: 0.99998135 | Q10: 0.99997221 | R10: 0.96997018 | S10: 0.40198022 | T10: 0.54630825 | U10: 0.9219314
A11: 1349353 | B11: =SUMPRODUCT(K11:N11,PAINEL_PESOS!$C$16:$C$19) | C11: =SUMPRODUCT(O11:Q11,PAINEL_PESOS!$C$21:$C$23) | D11: =SUMPRODUCT(R11:S11,PAINEL_PESOS!$C$25:$C$26) | E11: =SUMPRODUCT(T11:U11,PAINEL_PESOS!$C$28:$C$29) | F11: 0.99998016 | G11: 0.73165797 | H11: =IF(NOT(AND(PAINEL_PESOS!$D$12="OK - 100%",PAINEL_PESOS!$F$20="OK - 100%",PAINEL_PESOS!$F$24="OK - 100%",PAINEL_PESOS!$F$27="OK - 100%",PAINEL_PESOS!$F$30="OK - 100%")),"", (B11*PAINEL_PESOS!$B$7+C11*PAINEL_PESOS!$B$8+D11*PAINEL_PESOS!$B$9+E11*PAINEL_PESOS!$B$10)*F11) | I11: =IF(H11="","",H11-G11) | J11: =IF(I11="","",ABS(I11)) | K11: 0.90271808 | L11: 0 | M11: 0.99484738 | N11: 0.99988833 | O11: 0.27238502 | P11: 0.99993959 | Q11: 0.99997803 | R11: 0.95294454 | S11: 0.48710926 | T11: 0.53396597 | U11: 0.91576478
A12: 1349354 | B12: =SUMPRODUCT(K12:N12,PAINEL_PESOS!$C$16:$C$19) | C12: =SUMPRODUCT(O12:Q12,PAINEL_PESOS!$C$21:$C$23) | D12: =SUMPRODUCT(R12:S12,PAINEL_PESOS!$C$25:$C$26) | E12: =SUMPRODUCT(T12:U12,PAINEL_PESOS!$C$28:$C$29) | F12: 0.99995872 | G12: 0.68832404 | H12: =IF(NOT(AND(PAINEL_PESOS!$D$12="OK - 100%",PAINEL_PESOS!$F$20="OK - 100%",PAINEL_PESOS!$F$24="OK - 100%",PAINEL_PESOS!$F$27="OK - 100%",PAINEL_PESOS!$F$30="OK - 100%")),"", (B12*PAINEL_PESOS!$B$7+C12*PAINEL_PESOS!$B$8+D12*PAINEL_PESOS!$B$9+E12*PAINEL_PESOS!$B$10)*F12) | I12: =IF(H12="","",H12-G12) | J12: =IF(I12="","",ABS(I12)) | K12: 0.40749113 | L12: 0 | M12: 0.97135628 | N12: 0.99981607 | O12: 0.33951557 | P12: 0.99999444 | Q12: 0.99990446 | R12: 0.94998151 | S12: 0.37505472 | T12: 0.55592991 | U12: 0.87691207
A13: 1349355 | B13: =SUMPRODUCT(K13:N13,PAINEL_PESOS!$C$16:$C$19) | C13: =SUMPRODUCT(O13:Q13,PAINEL_PESOS!$C$21:$C$23) | D13: =SUMPRODUCT(R13:S13,PAINEL_PESOS!$C$25:$C$26) | E13: =SUMPRODUCT(T13:U13,PAINEL_PESOS!$C$28:$C$29) | F13: 0.99995556 | G13: 0.69142805 | H13: =IF(NOT(AND(PAINEL_PESOS!$D$12="OK - 100%",PAINEL_PESOS!$F$20="OK - 100%",PAINEL_PESOS!$F$24="OK - 100%",PAINEL_PESOS!$F$27="OK - 100%",PAINEL_PESOS!$F$30="OK - 100%")),"", (B13*PAINEL_PESOS!$B$7+C13*PAINEL_PESOS!$B$8+D13*PAINEL_PESOS!$B$9+E13*PAINEL_PESOS!$B$10)*F13) | I13: =IF(H13="","",H13-G13) | J13: =IF(I13="","",ABS(I13)) | K13: 0.40968044 | L13: 0 | M13: 0.96873322 | N13: 0.99980303 | O13: 0.34647036 | P13: 0.99999551 | Q13: 0.99989624 | R13: 0.96885954 | S13: 0.35518331 | T13: 0.57751325 | U13: 0.87676443
... A84: 1350935 | B84: =SUMPRODUCT(K84:N84,PAINEL_PESOS!$C$16:$C$19) | C84: =SUMPRODUCT(O84:Q84,PAINEL_PESOS!$C$21:$C$23) | D84: =SUMPRODUCT(R84:S84,PAINEL_PESOS!$C$25:$C$26) | E84: =SUMPRODUCT(T84:U84,PAINEL_PESOS!$C$28:$C$29) | F84: 0.96533027 | G84: 0.59907805 | H84: =IF(NOT(AND(PAINEL_PESOS!$D$12="OK - 100%",PAINEL_PESOS!$F$20="OK - 100%",PAINEL_PESOS!$F$24="OK - 100%",PAINEL_PESOS!$F$27="OK - 100%",PAINEL_PESOS!$F$30="OK - 100%")),"", (B84*PAINEL_PESOS!$B$7+C84*PAINEL_PESOS!$B$8+D84*PAINEL_PESOS!$B$9+E84*PAINEL_PESOS!$B$10)*F84) | I84: =IF(H84="","",H84-G84) | J84: =IF(I84="","",ABS(I84)) | K84: 0.52032379 | L84: 0 | M84: 0.65915619 | N84: 0.99563722 | O84: 0.56644712 | P84: 0.96721019 | Q84: 0.8405915 | R84: 0.32453047 | S84: 0.84787884 | T84: 0.3706371 | U84: 0.75131342
A85: 1349927 | B85: =SUMPRODUCT(K85:N85,PAINEL_PESOS!$C$16:$C$19) | C85: =SUMPRODUCT(O85:Q85,PAINEL_PESOS!$C$21:$C$23) | D85: =SUMPRODUCT(R85:S85,PAINEL_PESOS!$C$25:$C$26) | E85: =SUMPRODUCT(T85:U85,PAINEL_PESOS!$C$28:$C$29) | F85: 0.9997546 | H85: =IF(NOT(AND(PAINEL_PESOS!$D$12="OK - 100%",PAINEL_PESOS!$F$20="OK - 100%",PAINEL_PESOS!$F$24="OK - 100%",PAINEL_PESOS!$F$27="OK - 100%",PAINEL_PESOS!$F$30="OK - 100%")),"", (B85*PAINEL_PESOS!$B$7+C85*PAINEL_PESOS!$B$8+D85*PAINEL_PESOS!$B$9+E85*PAINEL_PESOS!$B$10)*F85) | I85: =IF(H85="","",H85-G85) | J85: =IF(I85="","",ABS(I85)) | K85: 0.2 | L85: 0 | M85: 1 | N85: 0.99797107 | O85: 0.22190574 | P85: 1 | Q85: 0.99994699 | R85: 0.34878724 | S85: 0.61210124 | U85: 0.82609391
A86: 1350936 | B86: =SUMPRODUCT(K86:N86,PAINEL_PESOS!$C$16:$C$19) | C86: =SUMPRODUCT(O86:Q86,PAINEL_PESOS!$C$21:$C$23) | D86: =SUMPRODUCT(R86:S86,PAINEL_PESOS!$C$25:$C$26) | E86: =SUMPRODUCT(T86:U86,PAINEL_PESOS!$C$28:$C$29) | F86: 0.98265978 | G86: 0.62606366 | H86: =IF(NOT(AND(PAINEL_PESOS!$D$12="OK - 100%",PAINEL_PESOS!$F$20="OK - 100%",PAINEL_PESOS!$F$24="OK - 100%",PAINEL_PESOS!$F$27="OK - 100%",PAINEL_PESOS!$F$30="OK - 100%")),"", (B86*PAINEL_PESOS!$B$7+C86*PAINEL_PESOS!$B$8+D86*PAINEL_PESOS!$B$9+E86*PAINEL_PESOS!$B$10)*F86) | I86: =IF(H86="","",H86-G86) | J86: =IF(I86="","",ABS(I86)) | K86: 0.82683495 | L86: 0 | M86: 0.7804823 | N86: 0.997349 | O86: 0.40304741 | P86: 0.98829636 | Q86: 0.91949806 | R86: 0.43682248 | S86: 0.73063492 | T86: 0.31601119 | U86: 0.77052753
A87: 1348880 | B87: =SUMPRODUCT(K87:N87,PAINEL_PESOS!$C$16:$C$19) | C87: =SUMPRODUCT(O87:Q87,PAINEL_PESOS!$C$21:$C$23) | D87: =SUMPRODUCT(R87:S87,PAINEL_PESOS!$C$25:$C$26) | E87: =SUMPRODUCT(T87:U87,PAINEL_PESOS!$C$28:$C$29) | F87: 0.99987109 | G87: 0.61632943 | H87: =IF(NOT(AND(PAINEL_PESOS!$D$12="OK - 100%",PAINEL_PESOS!$F$20="OK - 100%",PAINEL_PESOS!$F$24="OK - 100%",PAINEL_PESOS!$F$27="OK - 100%",PAINEL_PESOS!$F$30="OK - 100%")),"", (B87*PAINEL_PESOS!$B$7+C87*PAINEL_PESOS!$B$8+D87*PAINEL_PESOS!$B$9+E87*PAINEL_PESOS!$B$10)*F87) | I87: =IF(H87="","",H87-G87) | J87: =IF(I87="","",ABS(I87)) | K87: 0.2 | L87: 0 | M87: 0.24326629 | N87: 0.99898516 | O87: 0.33205015 | P87: 0.99999004 | Q87: 0.99996417 | R87: 0.99723074 | S87: 0.43442923 | T87: 0.36063911 | U87: 0.86317675
A88: 1350937 | B88: =SUMPRODUCT(K88:N88,PAINEL_PESOS!$C$16:$C$19) | C88: =SUMPRODUCT(O88:Q88,PAINEL_PESOS!$C$21:$C$23) | D88: =SUMPRODUCT(R88:S88,PAINEL_PESOS!$C$25:$C$26) | E88: =SUMPRODUCT(T88:U88,PAINEL_PESOS!$C$28:$C$29) | F88: 0.97708499 | G88: 0.61639991 | H88: =IF(NOT(AND(PAINEL_PESOS!$D$12="OK - 100%",PAINEL_PESOS!$F$20="OK - 100%",PAINEL_PESOS!$F$24="OK - 100%",PAINEL_PESOS!$F$27="OK - 100%",PAINEL_PESOS!$F$30="OK - 100%")),"", (B88*PAINEL_PESOS!$B$7+C88*PAINEL_PESOS!$B$8+D88*PAINEL_PESOS!$B$9+E88*PAINEL_PESOS!$B$10)*F88) | I88: =IF(H88="","",H88-G88) | J88: =IF(I88="","",ABS(I88)) | K88: 0.64171534 | L88: 0 | M88: 0.70726713 | N88: 0.99608859 | O88: 0.4696468 | P88: 0.99446547 | Q88: 0.89330744 | R88: 0.41128986 | S88: 0.84563821 | T88: 0.30150542 | U88: 0.74426565
A89: 1350938 | B89: =SUMPRODUCT(K89:N89,PAINEL_PESOS!$C$16:$C$19) | C89: =SUMPRODUCT(O89:Q89,PAINEL_PESOS!$C$21:$C$23) | D89: =SUMPRODUCT(R89:S89,PAINEL_PESOS!$C$25:$C$26) | E89: =SUMPRODUCT(T89:U89,PAINEL_PESOS!$C$28:$C$29) | F89: 0.98335607 | G89: 0.61002252 | H89: =IF(NOT(AND(PAINEL_PESOS!$D$12="OK - 100%",PAINEL_PESOS!$F$20="OK - 100%",PAINEL_PESOS!$F$24="OK - 100%",PAINEL_PESOS!$F$27="OK - 100%",PAINEL_PESOS!$F$30="OK - 100%")),"", (B89*PAINEL_PESOS!$B$7+C89*PAINEL_PESOS!$B$8+D89*PAINEL_PESOS!$B$9+E89*PAINEL_PESOS!$B$10)*F89) | I89: =IF(H89="","",H89-G89) | J89: =IF(I89="","",ABS(I89)) | K89: 0.51274013 | L89: 0 | M89: 0.68098439 | N89: 0.98006245 | O89: 0.4140927 | P89: 0.99261282 | Q89: 0.93088055 | R89: 0.52395096 | S89: 0.83941298 | T89: 0.42382526 | U89: 0.53030688
A90: 1350939 | B90: =SUMPRODUCT(K90:N90,PAINEL_PESOS!$C$16:$C$19) | C90: =SUMPRODUCT(O90:Q90,PAINEL_PESOS!$C$21:$C$23) | D90: =SUMPRODUCT(R90:S90,PAINEL_PESOS!$C$25:$C$26) | E90: =SUMPRODUCT(T90:U90,PAINEL_PESOS!$C$28:$C$29) | F90: 0.97496122 | G90: 0.55517528 | H90: =IF(NOT(AND(PAINEL_PESOS!$D$12="OK - 100%",PAINEL_PESOS!$F$20="OK - 100%",PAINEL_PESOS!$F$24="OK - 100%",PAINEL_PESOS!$F$27="OK - 100%",PAINEL_PESOS!$F$30="OK - 100%")),"", (B90*PAINEL_PESOS!$B$7+C90*PAINEL_PESOS!$B$8+D90*PAINEL_PESOS!$B$9+E90*PAINEL_PESOS!$B$10)*F90) | I90: =IF(H90="","",H90-G90) | J90: =IF(I90="","",ABS(I90)) | K90: 0.6379898 | L90: 0 | M90: 0.64712566 | N90: 0.96605632 | O90: 0.39565821 | P90: 0.9693035 | Q90: 0.90016627 | R90: 0.42011321 | S90: 0.43842295 | T90: 0.40261879 | U90: 0.65863937
A91: 1350940 | B91: =SUMPRODUCT(K91:N91,PAINEL_PESOS!$C$16:$C$19) | C91: =SUMPRODUCT(O91:Q91,PAINEL_PESOS!$C$21:$C$23) | D91: =SUMPRODUCT(R91:S91,PAINEL_PESOS!$C$25:$C$26) | E91: =SUMPRODUCT(T91:U91,PAINEL_PESOS!$C$28:$C$29) | F91: 0.9820394 | G91: 0.63444527 | H91: =IF(NOT(AND(PAINEL_PESOS!$D$12="OK - 100%",PAINEL_PESOS!$F$20="OK - 100%",PAINEL_PESOS!$F$24="OK - 100%",PAINEL_PESOS!$F$27="OK - 100%",PAINEL_PESOS!$F$30="OK - 100%")),"", (B91*PAINEL_PESOS!$B$7+C91*PAINEL_PESOS!$B$8+D91*PAINEL_PESOS!$B$9+E91*PAINEL_PESOS!$B$10)*F91) | I91: =IF(H91="","",H91-G91) | J91: =IF(I91="","",ABS(I91)) | K91: 0.88815942 | L91: 0 | M91: 0.58235611 | N91: 0.99546003 | O91: 0.3501426 | P91: 0.99281461 | Q91: 0.91668057 | R91: 0.50933697 | S91: 0.84017709 | T91: 0.44140309 | U91: 0.63805945
A92: 1350941 | B92: =SUMPRODUCT(K92:N92,PAINEL_PESOS!$C$16:$C$19) | C92: =SUMPRODUCT(O92:Q92,PAINEL_PESOS!$C$21:$C$23) | D92: =SUMPRODUCT(R92:S92,PAINEL_PESOS!$C$25:$C$26) | E92: =SUMPRODUCT(T92:U92,PAINEL_PESOS!$C$28:$C$29) | F92: 0.97335556 | G92: 0.57320343 | H92: =IF(NOT(AND(PAINEL_PESOS!$D$12="OK - 100%",PAINEL_PESOS!$F$20="OK - 100%",PAINEL_PESOS!$F$24="OK - 100%",PAINEL_PESOS!$F$27="OK - 100%",PAINEL_PESOS!$F$30="OK - 100%")),"", (B92*PAINEL_PESOS!$B$7+C92*PAINEL_PESOS!$B$8+D92*PAINEL_PESOS!$B$9+E92*PAINEL_PESOS!$B$10)*F92) | I92: =IF(H92="","",H92-G92) | J92: =IF(I92="","",ABS(I92)) | K92: 0.6177618 | L92: 0 | M92: 0.66642126 | N92: 0.88252096 | O92: 0.50350868 | P92: 0.95066321 | Q92: 0.97019361 | R92: 0.3067833 | S92: 0.60163306 | T92: 0.39077097 | U92: 0.71237048
A93: 1350942 | B93: =SUMPRODUCT(K93:N93,PAINEL_PESOS!$C$16:$C$19) | C93: =SUMPRODUCT(O93:Q93,PAINEL_PESOS!$C$21:$C$23) | D93: =SUMPRODUCT(R93:S93,PAINEL_PESOS!$C$25:$C$26) | E93: =SUMPRODUCT(T93:U93,PAINEL_PESOS!$C$28:$C$29) | F93: 0.98836176 | G93: 0.61444508 | H93: =IF(NOT(AND(PAINEL_PESOS!$D$12="OK - 100%",PAINEL_PESOS!$F$20="OK - 100%",PAINEL_PESOS!$F$24="OK - 100%",PAINEL_PESOS!$F$27="OK - 100%",PAINEL_PESOS!$F$30="OK - 100%")),"", (B93*PAINEL_PESOS!$B$7+C93*PAINEL_PESOS!$B$8+D93*PAINEL_PESOS!$B$9+E93*PAINEL_PESOS!$B$10)*F93) | I93: =IF(H93="","",H93-G93) | J93: =IF(I93="","",ABS(I93)) | K93: 0.64262318 | L93: 0 | M93: 0.71039798 | N93: 0.99347533 | O93: 0.38258201 | P93: 0.99256136 | Q93: 0.94845677 | R93: 0.32724036 | S93: 0.82026076 | T93: 0.3662954 | U93: 0.73733123
A94: 1350943 | B94: =SUMPRODUCT(K94:N94,PAINEL_PESOS!$C$16:$C$19) | C94: =SUMPRODUCT(O94:Q94,PAINEL_PESOS!$C$21:$C$23) | D94: =SUMPRODUCT(R94:S94,PAINEL_PESOS!$C$25:$C$26) | E94: =SUMPRODUCT(T94:U94,PAINEL_PESOS!$C$28:$C$29) | F94: 0.96184678 | G94: 0.57090261 | H94: =IF(NOT(AND(PAINEL_PESOS!$D$12="OK - 100%",PAINEL_PESOS!$F$20="OK - 100%",PAINEL_PESOS!$F$24="OK - 100%",PAINEL_PESOS!$F$27="OK - 100%",PAINEL_PESOS!$F$30="OK - 100%")),"", (B94*PAINEL_PESOS!$B$7+C94*PAINEL_PESOS!$B$8+D94*PAINEL_PESOS!$B$9+E94*PAINEL_PESOS!$B$10)*F94) | I94: =IF(H94="","",H94-G94) | J94: =IF(I94="","",ABS(I94)) | K94: 0.63953449 | L94: 0 | M94: 0.66612381 | N94: 0.8917769 | O94: 0.50647999 | P94: 0.89264501 | Q94: 0.96106731 | R94: 0.26418932 | S94: 0.71175856 | T94: 0.31919309 | U94: 0.78106703
A95: 1350944 | B95: =SUMPRODUCT(K95:N95,PAINEL_PESOS!$C$16:$C$19) | C95: =SUMPRODUCT(O95:Q95,PAINEL_PESOS!$C$21:$C$23) | D95: =SUMPRODUCT(R95:S95,PAINEL_PESOS!$C$25:$C$26) | E95: =SUMPRODUCT(T95:U95,PAINEL_PESOS!$C$28:$C$29) | F95: 0.99343872 | G95: 0.58822328 | H95: =IF(NOT(AND(PAINEL_PESOS!$D$12="OK - 100%",PAINEL_PESOS!$F$20="OK - 100%",PAINEL_PESOS!$F$24="OK - 100%",PAINEL_PESOS!$F$27="OK - 100%",PAINEL_PESOS!$F$30="OK - 100%")),"", (B95*PAINEL_PESOS!$B$7+C95*PAINEL_PESOS!$B$8+D95*PAINEL_PESOS!$B$9+E95*PAINEL_PESOS!$B$10)*F95) | I95: =IF(H95="","",H95-G95) | J95: =IF(I95="","",ABS(I95)) | K95: 0.6807472 | L95: 0 | M95: 0.69702386 | N95: 0.99520099 | O95: 0.29186481 | P95: 0.9882768 | Q95: 0.97296588 | R95: 0.21726685 | S95: 0.7333559 | T95: 0.36521359 | U95: 0.7324721
A96: 1350945 | B96: =SUMPRODUCT(K96:N96,PAINEL_PESOS!$C$16:$C$19) | C96: =SUMPRODUCT(O96:Q96,PAINEL_PESOS!$C$21:$C$23) | D96: =SUMPRODUCT(R96:S96,PAINEL_PESOS!$C$25:$C$26) | E96: =SUMPRODUCT(T96:U96,PAINEL_PESOS!$C$28:$C$29) | F96: 0.98865032 | G96: 0.50645635 | H96: =IF(NOT(AND(PAINEL_PESOS!$D$12="OK - 100%",PAINEL_PESOS!$F$20="OK - 100%",PAINEL_PESOS!$F$24="OK - 100%",PAINEL_PESOS!$F$27="OK - 100%",PAINEL_PESOS!$F$30="OK - 100%")),"", (B96*PAINEL_PESOS!$B$7+C96*PAINEL_PESOS!$B$8+D96*PAINEL_PESOS!$B$9+E96*PAINEL_PESOS!$B$10)*F96) | I96: =IF(H96="","",H96-G96) | J96: =IF(I96="","",ABS(I96)) | K96: 0.7538647 | L96: 0 | M96: 0.71517357 | N96: 0.9661318 | O96: 0.41967073 | P96: 0.93086002 | Q96: 0.97848017 | R96: 0.2270063 | S96: 0 | T96: 0.31588009 | U96: 0.78501831
A97: 1350946 | B97: =SUMPRODUCT(K97:N97,PAINEL_PESOS!$C$16:$C$19) | C97: =SUMPRODUCT(O97:Q97,PAINEL_PESOS!$C$21:$C$23) | D97: =SUMPRODUCT(R97:S97,PAINEL_PESOS!$C$25:$C$26) | E97: =SUMPRODUCT(T97:U97,PAINEL_PESOS!$C$28:$C$29) | F97: 0.9969672 | G97: 0.59780119 | H97: =IF(NOT(AND(PAINEL_PESOS!$D$12="OK - 100%",PAINEL_PESOS!$F$20="OK - 100%",PAINEL_PESOS!$F$24="OK - 100%",PAINEL_PESOS!$F$27="OK - 100%",PAINEL_PESOS!$F$30="OK - 100%")),"", (B97*PAINEL_PESOS!$B$7+C97*PAINEL_PESOS!$B$8+D97*PAINEL_PESOS!$B$9+E97*PAINEL_PESOS!$B$10)*F97) | I97: =IF(H97="","",H97-G97) | J97: =IF(I97="","",ABS(I97)) | K97: 0.76557714 | L97: 0 | M97: 0.69114233 | N97: 0.99436056 | O97: 0.32548226 | P97: 0.99071661 | Q97: 0.99031223 | R97: 0.20934959 | S97: 0.7101517 | T97: 0.31966263 | U97: 0.79457978
... A121: 1350970 | B121: =SUMPRODUCT(K121:N121,PAINEL_PESOS!$C$16:$C$19) | C121: =SUMPRODUCT(O121:Q121,PAINEL_PESOS!$C$21:$C$23) | D121: =SUMPRODUCT(R121:S121,PAINEL_PESOS!$C$25:$C$26) | E121: =SUMPRODUCT(T121:U121,PAINEL_PESOS!$C$28:$C$29) | F121: 0.82123714 | G121: 0.34493308 | H121: =IF(NOT(AND(PAINEL_PESOS!$D$12="OK - 100%",PAINEL_PESOS!$F$20="OK - 100%",PAINEL_PESOS!$F$24="OK - 100%",PAINEL_PESOS!$F$27="OK - 100%",PAINEL_PESOS!$F$30="OK - 100%")),"", (B121*PAINEL_PESOS!$B$7+C121*PAINEL_PESOS!$B$8+D121*PAINEL_PESOS!$B$9+E121*PAINEL_PESOS!$B$10)*F121) | I121: =IF(H121="","",H121-G121) | J121: =IF(I121="","",ABS(I121)) | K121: 0.8476251 | L121: 0 | M121: 0.54323353 | N121: 0 | O121: 0.53027008 | P121: 0 | Q121: 0.75087963 | R121: 0.23990107 | S121: 0.22159708 | T121: 0.65226772 | U121: 0.69683635
A122: 1350971 | B122: =SUMPRODUCT(K122:N122,PAINEL_PESOS!$C$16:$C$19) | C122: =SUMPRODUCT(O122:Q122,PAINEL_PESOS!$C$21:$C$23) | D122: =SUMPRODUCT(R122:S122,PAINEL_PESOS!$C$25:$C$26) | E122: =SUMPRODUCT(T122:U122,PAINEL_PESOS!$C$28:$C$29) | F122: 0.78146905 | H122: =IF(NOT(AND(PAINEL_PESOS!$D$12="OK - 100%",PAINEL_PESOS!$F$20="OK - 100%",PAINEL_PESOS!$F$24="OK - 100%",PAINEL_PESOS!$F$27="OK - 100%",PAINEL_PESOS!$F$30="OK - 100%")),"", (B122*PAINEL_PESOS!$B$7+C122*PAINEL_PESOS!$B$8+D122*PAINEL_PESOS!$B$9+E122*PAINEL_PESOS!$B$10)*F122) | I122: =IF(H122="","",H122-G122) | J122: =IF(I122="","",ABS(I122)) | K122: 1 | L122: 0 | M122: 0.36050698 | N122: 0 | O122: 0.78172324 | P122: 0 | Q122: 0.92193267 | R122: 0 | S122: 0.35147812 | U122: 0.82609391
A123: 1350972 | B123: =SUMPRODUCT(K123:N123,PAINEL_PESOS!$C$16:$C$19) | C123: =SUMPRODUCT(O123:Q123,PAINEL_PESOS!$C$21:$C$23) | D123: =SUMPRODUCT(R123:S123,PAINEL_PESOS!$C$25:$C$26) | E123: =SUMPRODUCT(T123:U123,PAINEL_PESOS!$C$28:$C$29) | F123: 0.75 | G123: 0.30653718 | H123: =IF(NOT(AND(PAINEL_PESOS!$D$12="OK - 100%",PAINEL_PESOS!$F$20="OK - 100%",PAINEL_PESOS!$F$24="OK - 100%",PAINEL_PESOS!$F$27="OK - 100%",PAINEL_PESOS!$F$30="OK - 100%")),"", (B123*PAINEL_PESOS!$B$7+C123*PAINEL_PESOS!$B$8+D123*PAINEL_PESOS!$B$9+E123*PAINEL_PESOS!$B$10)*F123) | I123: =IF(H123="","",H123-G123) | J123: =IF(I123="","",ABS(I123)) | K123: 0.66024436 | L123: 0 | M123: 0.44848665 | N123: 0 | O123: 0.66287188 | P123: 0 | Q123: 0.71606225 | R123: 0.18260179 | S123: 0.3067295 | T123: 0.65935051 | U123: 0.64739316
A124: 1350973 | B124: =SUMPRODUCT(K124:N124,PAINEL_PESOS!$C$16:$C$19) | C124: =SUMPRODUCT(O124:Q124,PAINEL_PESOS!$C$21:$C$23) | D124: =SUMPRODUCT(R124:S124,PAINEL_PESOS!$C$25:$C$26) | E124: =SUMPRODUCT(T124:U124,PAINEL_PESOS!$C$28:$C$29) | F124: 0.75 | G124: 0.30911466 | H124: =IF(NOT(AND(PAINEL_PESOS!$D$12="OK - 100%",PAINEL_PESOS!$F$20="OK - 100%",PAINEL_PESOS!$F$24="OK - 100%",PAINEL_PESOS!$F$27="OK - 100%",PAINEL_PESOS!$F$30="OK - 100%")),"", (B124*PAINEL_PESOS!$B$7+C124*PAINEL_PESOS!$B$8+D124*PAINEL_PESOS!$B$9+E124*PAINEL_PESOS!$B$10)*F124) | I124: =IF(H124="","",H124-G124) | J124: =IF(I124="","",ABS(I124)) | K124: 0.74186898 | L124: 0 | M124: 0.48387944 | N124: 0 | O124: 0.71059625 | P124: 0 | Q124: 0.39589423 | R124: 0.26256191 | S124: 0.35312324 | T124: 0.64733955 | U124: 0.6836638
